Workbook

Sheet DIA 01
B1: FECHA | E1: MGA CONTRATISTA MINERA S.A. DE C.V. | O1: ENTRADA DE DIESEL | P1: EXISTENCIA INICIAL DE DIESEL (LTS) | Q1: EXISTENCIA FINAL DE DIESEL (LTS)
B2: DIA | C2: MES | D2: AÑO | O2: 2100 | P2: 13309 | Q2: =P2-O35 -> 11756
A4: NO. DE EQUIPO | B4: PRIMER TURNO | I4: SEGUNDO TURNO
B6: Horometro Inicial 1ra | C6: DIESEL | D6: Nombre Operador | E6: Nombre Despachador | F6: Nombre del supervisor | G6: Horometro Final 1ra | I6: Horometro Inicial 2da | J6: =C6 -> DIESEL | K6: =D6 -> Nombre Operador | L6: =E6 -> Nombre Despachador | M6: =F6 -> Nombre del supervisor | N6: Horometro final 2da | O6: CONSUMO X DIA | P6: HRS 1ra | Q6: HRS 2da
A7: ST-031 (EPIROC 1030) | B7: 4848 | C7: 133 | D7: RAUL | E7: CESAR | F7: JESUS | O7: =C7+J7 -> 133 | P7: =G7-B7 -> -4848 | Q7: =N7-I7 -> 0
A8: ST-025 (1600) | O8: =C8+J8 -> 0 | P8: =G8-B8 -> 0 | Q8: =N8-I8 -> 0
A9: ST-036 R1300 | B9: 3909 | C9: 164 | D9: JESUS | E9: CESAR | F9: JESUS | I9: 8916.8 | J9: 90 | K9: JUAN | L9: LUIS | M9: ROBERTO | O9: =C9+J9 -> 254 | P9: =G9-B9 -> -3909 | Q9: =N9-I9 -> -8916.8
A10: ST-018 | O10: =C10+J10 -> 0 | P10: =G10-B10 -> 0 | Q10: =N10-I10 -> 0
A11: ST-034 KOMATSU | O11: =C11+J11 -> 0 | P11: =G11-B11 -> 0 | Q11: =N11-I11 -> 0
A12: JL-015 (DD311) | C12: 44 | D12: WILFREDO | E12: CESAR | F12: JESUS | O12: =C12+J12 -> 44 | P12: =G12-B12 -> 0 | Q12: =N12-I12 -> 0
A13: JL-019 | O13: =C13+J13 -> 0 | P13: =G13-B13 -> 0 | Q13: =N13-I13 -> 0
A14: JL-024 CANNON | O14: =C14+J14 -> 0 | P14: =G14-B14 -> 0 | Q14: =N14-I14 -> 0
A15: JA-007 RESEMIN | B15: 738.7 | C15: 31 | D15: HILARIO | E15: CESAR | F15: JESUS | O15: =C15+J15 -> 31 | P15: =G15-B15 -> -738.7 | Q15: =N15-I15 -> 0
A16: JA-004 CANNON | O16: =C16+J16 -> 0 | P16: =G16-B16 -> 0 | Q16: =N16-I16 -> 0
A17: RE-009 (RETROEXCAVADORA) | O17: =C17+J17 -> 0 | P17: =G17-B17 -> 0 | Q17: =N17-I17 -> 0
A18: RE-010 (RETROEXCAVADORA) | B18: 2728 | C18: 111 | D18: MARTHAA | E18: CESAR | F18: JESUS | O18: =C18+J18 -> 111 | P18: =G18-B18 -> -2728 | Q18: =N18-I18 -> 0
A19: ZN | O19: =C19+J19 -> 0 | P19: =G19-B19 -> 0 | Q19: =N19-I19 -> 0
A20: CBP-001 (BAJO PERFIL) | O20: =C20+J20 -> 0 | P20: =G20-B20 -> 0 | Q20: =N20-I20 -> 0
A21: MG-105 | O21: =C21+J21 -> 0 | P21: =G21-B21 -> 0 | Q21: =N21-I21 -> 0
A22: MG-044 | O22: =C22+J22 -> 0 | P22: =G22-B22 -> 0 | Q22: =N22-I22 -> 0
A23: MG-085 (POLVORERA) | O23: =C23+J23 -> 0 | P23: =G23-B23 -> 0 | Q23: =N23-I23 -> 0
A24: MG-033 (PERSONAL) | O24: =C24+J24 -> 0 | P24: =G24-B24 -> 0 | Q24: =N24-I24 -> 0
A25: MG-113 | O25: =C25+J25 -> 0 | P25: =G25-B25 -> 0 | Q25: =N25-I25 -> 0
A26: MG-121 | O26: =C26+J26 -> 0 | P26: =G26-B26 -> 0 | Q26: =N26-I26 -> 0
A27: MG-086 | B27: 86234 | C27: 84 | D27: FRANCISCO | E27: CESAR | F27: JESUS | O27: =C27+J27 -> 84 | P27: =G27-B27 -> -86234 | Q27: =N27-I27 -> 0
A28: MG-111 | O28: =C28+J28 -> 0 | P28: =G28-B28 -> 0 | Q28: =N28-I28 -> 0
A29: MG-120 | O29: =C29+J29 -> 0 | P29: =G29-B29 -> 0 | Q29: =N29-I29 -> 0
A30: PROSERMIN | C30: 250 | J30: 254 | O30: =C30+J30 -> 504 | P30: =G30-B30 -> 0 | Q30: =N30-I30 -> 0
A31: ST-060 | O31: =C31+J31 -> 0 | P31: =G31-B31 -> 0 | Q31: =N31-I31 -> 0
A32: ST-53 | O32: =C32+J32 -> 0 | P32: =G32-B32 -> 0 | Q32: =N32-I32 -> 0
A33: ST-039 | B33: 9378 | C33: 246 | D33: CARLOS | E33: CESAR | F33: JESUS | I33: 9384 | J33: 146 | K33: MISAEL | L33: LUIS | M33: ROBERTO | O33: =C33+J33 -> 392 | P33: =G33-B33 -> -9378 | Q33: =N33-I33 -> -9384
A34: JL-025 | P34: =G34-B34 -> 0 | Q34: =N34-I34 -> 0
A35: TOTALES | C35: =SUM(C7:C34) -> 1063 | J35: =SUM(J7:J34) -> 490 | O35: =C35+J35 -> 1553
A38: NOMBRE Y FIRMA DE QUIEN AUTORIZA | G38: NOMBRE Y FIRMA DE ALMACEN | O38: ADMINISTRADOR
P40: 44237 | R40: 44244 | T40: 44251
O41: ACEITE | P41: TAMBO | Q41: LTS | R41: TAMBO | S41: LTS | T41: TAMBO | U41: LTS
O42: HIDRAULICO | P42: 3 | R42: 2 | S42: 140 | T42: 0 | U42: 155
O43: MOTOR | P43: 3 | Q43: 70 | R43: 2 | S43: 182 | T43: 2 | U43: 170
O44: DIFERENCIAL | P44: 1 | Q44: 137 | R44: 1 | S44: 137 | T44: 1 | U44: 160
O45: MAQ.PERF. | P45: 2 | Q45: 117 | R45: 2 | S45: 27 | T45: 1 | U45: 150
...

Sheet DIA 02
B1: FECHA | E1: MGA CONTRATISTA MINERA S.A. DE C.V. | O1: ENTRADA DE DIESEL | P1: EXISTENCIA INICIAL DE DIESEL (LTS) | Q1: EXISTENCIA FINAL DE DIESEL (LTS)
B2: DIA | C2: MES | D2: AÑO | P2: ='DIA 01'!Q2+O2 -> 11756 | Q2: =P2-O35 -> 10038
A4: NO. DE EQUIPO | B4: PRIMER TURNO | I4: SEGUNDO TURNO
B6: Horometro Inicial 1ra | C6: DIESEL | D6: Nombre Operador | E6: Nombre Despachador | F6: Nombre del supervisor | G6: Horometro Final 1ra | I6: Horometro Inicial 2da | J6: =C6 -> DIESEL | K6: =D6 -> Nombre Operador | L6: =E6 -> Nombre Despachador | M6: =F6 -> Nombre del supervisor | N6: Horometro final 2da | O6: ='DIA 01'!O6 -> CONSUMO X DIA | P6: HRS 1ra | Q6: HRS 2da
A7: ='DIA 01'!A7 -> ST-031 (EPIROC 1030) | I7: 4855.1 | J7: 115 | K7: JUAN | L7: LUIS | M7: ROBERTO | O7: =C7+J7 -> 115 | P7: =G7-B7 -> 0 | Q7: =N7-I7 -> -4855.1
A8: ='DIA 01'!A8 -> ST-025 (1600) | O8: =C8+J8 -> 0 | P8: =G8-B8 -> 0 | Q8: =N8-I8 -> 0
A9: ='DIA 01'!A9 -> ST-036 R1300 | B9: 8926 | C9: 270 | D9: JESUS | E9: CESAR | F9: JESUS | J9: 90 | K9: JUAN | L9: LUIS | M9: ROBERTO | O9: =C9+J9 -> 360 | P9: =G9-B9 -> -8926 | Q9: =N9-I9 -> 0
A10: ='DIA 01'!A10 -> ST-018 | I10: 95795 | J10: 146 | K10: JUAN | L10: LUIS | M10: ROBERTO | O10: =C10+J10 -> 146 | P10: =G10-B10 -> 0 | Q10: =N10-I10 -> -95795
A11: ='DIA 01'!A11 -> ST-034 KOMATSU | O11: =C11+J11 -> 0 | P11: =G11-B11 -> 0 | Q11: =N11-I11 -> 0
A12: ='DIA 01'!A12 -> JL-015 (DD311) | O12: =C12+J12 -> 0 | P12: =G12-B12 -> 0 | Q12: =N12-I12 -> 0
A13: ='DIA 01'!A13 -> JL-019 | O13: =C13+J13 -> 0 | P13: =G13-B13 -> 0 | Q13: =N13-I13 -> 0
A14: ='DIA 01'!A14 -> JL-024 CANNON | O14: =C14+J14 -> 0 | P14: =G14-B14 -> 0 | Q14: =N14-I14 -> 0
A15: ='DIA 01'!A15 -> JA-007 RESEMIN | O15: =C15+J15 -> 0 | P15: =G15-B15 -> 0 | Q15: =N15-I15 -> 0
A16: ='DIA 01'!A16 -> JA-004 CANNON | O16: =C16+J16 -> 0 | P16: =G16-B16 -> 0 | Q16: =N16-I16 -> 0
A17: ='DIA 01'!A17 -> RE-009 (RETROEXCAVADORA) | B17: 6580.5 | C17: 63 | D17: ADRIAN | E17: CESAR | F17: JESUS | O17: =C17+J17 -> 63 | P17: =G17-B17 -> -6580.5 | Q17: =N17-I17 -> 0
A18: ='DIA 01'!A18 -> RE-010 (RETROEXCAVADORA) | O18: =C18+J18 -> 0 | P18: =G18-B18 -> 0 | Q18: =N18-I18 -> 0
A19: ='DIA 01'!A19 -> ZN | O19: =C19+J19 -> 0 | P19: =G19-B19 -> 0 | Q19: =N19-I19 -> 0
A20: ='DIA 01'!A20 -> CBP-001 (BAJO PERFIL) | O20: =C20+J20 -> 0 | P20: =G20-B20 -> 0 | Q20: =N20-I20 -> 0
A21: ='DIA 01'!A21 -> MG-105 | O21: =C21+J21 -> 0 | P21: =G21-B21 -> 0 | Q21: =N21-I21 -> 0
A22: ='DIA 01'!A22 -> MG-044 | I22: 510466 | J22: 76 | K22: MIGUEL | L22: LUIS | M22: ROBERTO | O22: =C22+J22 -> 76 | P22: =G22-B22 -> 0 | Q22: =N22-I22 -> -510466
A23: ='DIA 01'!A23 -> MG-085 (POLVORERA) | O23: =C23+J23 -> 0 | P23: =G23-B23 -> 0 | Q23: =N23-I23 -> 0
A24: ='DIA 01'!A24 -> MG-033 (PERSONAL) | O24: =C24+J24 -> 0 | P24: =G24-B24 -> 0 | Q24: =N24-I24 -> 0
A25: ='DIA 01'!A25 -> MG-113 | O25: =C25+J25 -> 0 | P25: =G25-B25 -> 0 | Q25: =N25-I25 -> 0
A26: ='DIA 01'!A26 -> MG-121 | O26: =C26+J26 -> 0 | P26: =G26-B26 -> 0 | Q26: =N26-I26 -> 0
A27: ='DIA 01'!A27 -> MG-086 | O27: =C27+J27 -> 0 | P27: =G27-B27 -> 0 | Q27: =N27-I27 -> 0
A28: ='DIA 01'!A28 -> MG-111 | O28: =C28+J28 -> 0 | P28: =G28-B28 -> 0 | Q28: =N28-I28 -> 0
A29: ='DIA 01'!A29 -> MG-120 | O29: =C29+J29 -> 0 | P29: =G29-B29 -> 0 | Q29: =N29-I29 -> 0
A30: ='DIA 01'!A30 -> PROSERMIN | C30: 260 | J30: 286 | O30: =C30+J30 -> 546 | P30: =G30-B30 -> 0 | Q30: =N30-I30 -> 0
A31: ='DIA 01'!A31 -> ST-060 | O31: =C31+J31 -> 0 | P31: =G31-B31 -> 0 | Q31: =N31-I31 -> 0
A32: ='DIA 01'!A32 -> ST-53 | O32: =C32+J32 -> 0 | P32: =G32-B32 -> 0 | Q32: =N32-I32 -> 0
A33: ='DIA 01'!A33 -> ST-039 | B33: 9393.2 | C33: 217 | D33: CARLOS | E33: CESAR | F33: JESUS | I33: 9404 | J33: 195 | K33: MISAEL | L33: LUIS | M33: ROBERTO | O33: =C33+J33 -> 412 | P33: =G33-B33 -> -9393.2 | Q33: =N33-I33 -> -9404
A34: ='DIA 01'!A34 -> JL-025 | O34: =C34+J34 -> 0 | P34: =G34-B34 -> 0 | Q34: =N34-I34 -> 0
A35: TOTALES | C35: =SUM(C7:C34) -> 810 | J35: =SUM(J7:J34) -> 908 | O35: =C35+J35 -> 1718
A43: NOMBRE Y FIRMA DE QUIEN AUTORIZA | G43: NOMBRE Y FIRMA DE ALMACEN | O43: ADMINISTRADOR
P45: 44237 | R45: 44244 | T45: 44251
O46: ACEITE | P46: TAMBO | Q46: LTS | R46: TAMBO | S46: LTS | T46: TAMBO | U46: LTS
O47: HIDRAULICO | P47: 3 | R47: 2 | S47: 140 | T47: 0 | U47: 155
O48: MOTOR | P48: 3 | Q48: 70 | R48: 2 | S48: 182 | T48: 2 | U48: 170
O49: DIFERENCIAL | P49: 1 | Q49: 137 | R49: 1 | S49: 137 | T49: 1 | U49: 160
O50: MAQ.PERF. | P50: 2 | Q50: 117 | R50: 2 | S50: 27 | T50: 1 | U50: 150
...

Sheet DIA 03
B1: FECHA | E1: MGA CONTRATISTA MINERA S.A. DE C.V. | O1: ENTRADA DE DIESEL | P1: EXISTENCIA INICIAL DE DIESEL (LTS) | Q1: EXISTENCIA FINAL DE DIESEL (LTS)
B2: DIA | C2: MES | D2: AÑO | O2: 2137 | P2: ='DIA 02'!Q2+O2 -> 12175 | Q2: =P2-O35 -> 10367
A4: NO. DE EQUIPO | B4: PRIMER TURNO | I4: SEGUNDO TURNO
B6: Horometro Inicial 1ra | C6: DIESEL | D6: Nombre Operador | E6: Nombre Despachador | F6: Nombre del supervisor | G6: Horometro Final 1ra | I6: Horometro Inicial 2da | J6: =C6 -> DIESEL | K6: =D6 -> Nombre Operador | L6: =E6 -> Nombre Despachador | M6: =F6 -> Nombre del supervisor | N6: Horometro final 2da | O6: ='DIA 02'!O6 -> CONSUMO X DIA | P6: HRS 1ra | Q6: HRS 2da
A7: ='DIA 02'!A7 -> ST-031 (EPIROC 1030) | O7: =C7+J7 -> 0 | P7: =G7-B7 -> 0 | Q7: =N7-I7 -> 0
A8: ='DIA 02'!A8 -> ST-025 (1600) | O8: =C8+J8 -> 0 | P8: =G8-B8 -> 0 | Q8: =N8-I8 -> 0
A9: ='DIA 02'!A9 -> ST-036 R1300 | B9: 8941.6 | C9: 198 | D9: JESUS | E9: CESAR | F9: JESUS | I9: 89499 | J9: 345 | K9: JUAN | L9: LUIS | M9: ROBERTO | O9: =C9+J9 -> 543 | P9: =G9-B9 -> -8941.6 | Q9: =N9-I9 -> -89499
A10: ='DIA 02'!A10 -> ST-018 | I10: 9587 | J10: 182 | K10: MISAEL | L10: LUIS | M10: ROBERTO | O10: =C10+J10 -> 182 | P10: =G10-B10 -> 0 | Q10: =N10-I10 -> -9587
A11: ='DIA 02'!A11 -> ST-034 KOMATSU | O11: =C11+J11 -> 0 | P11: =G11-B11 -> 0 | Q11: =N11-I11 -> 0
A12: ='DIA 02'!A12 -> JL-015 (DD311) | O12: =C12+J12 -> 0 | P12: =G12-B12 -> 0 | Q12: =N12-I12 -> 0
A13: ='DIA 02'!A13 -> JL-019 | O13: =C13+J13 -> 0 | P13: =G13-B13 -> 0 | Q13: =N13-I13 -> 0
A14: ='DIA 02'!A14 -> JL-024 CANNON | O14: =C14+J14 -> 0 | P14: =G14-B14 -> 0 | Q14: =N14-I14 -> 0
A15: ='DIA 02'!A15 -> JA-007 RESEMIN | B15: 745.7 | C15: 30 | D15: HILARIO | E15: CESARR | F15: JESUS | O15: =C15+J15 -> 30 | P15: =G15-B15 -> -745.7 | Q15: =N15-I15 -> 0
A16: ='DIA 02'!A16 -> JA-004 CANNON | O16: =C16+J16 -> 0 | P16: =G16-B16 -> 0 | Q16: =N16-I16 -> 0
A17: ='DIA 02'!A17 -> RE-009 (RETROEXCAVADORA) | O17: =C17+J17 -> 0 | P17: =G17-B17 -> 0 | Q17: =N17-I17 -> 0
A18: ='DIA 02'!A18 -> RE-010 (RETROEXCAVADORA) | I18: 6599.5 | J18: 93 | K18: FELIX | L18: LUIS | M18: ROBERTO | O18: =C18+J18 -> 93 | P18: =G18-B18 -> 0 | Q18: =N18-I18 -> -6599.5
A19: ='DIA 02'!A19 -> ZN | O19: =C19+J19 -> 0 | P19: =G19-B19 -> 0 | Q19: =N19-I19 -> 0
A20: ='DIA 02'!A20 -> CBP-001 (BAJO PERFIL) | O20: =C20+J20 -> 0 | P20: =G20-B20 -> 0 | Q20: =N20-I20 -> 0
A21: ='DIA 02'!A21 -> MG-105 | O21: =C21+J21 -> 0 | P21: =G21-B21 -> 0 | Q21: =N21-I21 -> 0
A22: ='DIA 02'!A22 -> MG-044 | O22: =C22+J22 -> 0 | P22: =G22-B22 -> 0 | Q22: =N22-I22 -> 0
A23: ='DIA 02'!A23 -> MG-085 (POLVORERA) | O23: =C23+J23 -> 0 | P23: =G23-B23 -> 0 | Q23: =N23-I23 -> 0
A24: ='DIA 02'!A24 -> MG-033 (PERSONAL) | O24: =C24+J24 -> 0 | P24: =G24-B24 -> 0 | Q24: =N24-I24 -> 0
A25: ='DIA 02'!A25 -> MG-113 | O25: =C25+J25 -> 0 | P25: =G25-B25 -> 0 | Q25: =N25-I25 -> 0
A26: ='DIA 02'!A26 -> MG-121 | B26: 24878 | C26: 62 | D26: REYNALDO | E26: CESAR | O26: =C26+J26 -> 62 | P26: =G26-B26 -> -24878 | Q26: =N26-I26 -> 0
A27: ='DIA 02'!A27 -> MG-086 | O27: =C27+J27 -> 0 | P27: =G27-B27 -> 0 | Q27: =N27-I27 -> 0
A28: ='DIA 02'!A28 -> MG-111 | O28: =C28+J28 -> 0 | P28: =G28-B28 -> 0 | Q28: =N28-I28 -> 0
A29: ='DIA 02'!A29 -> MG-120 | O29: =C29+J29 -> 0 | P29: =G29-B29 -> 0 | Q29: =N29-I29 -> 0
A30: ='DIA 02'!A30 -> PROSERMIN | C30: 141 | J30: 236 | O30: =C30+J30 -> 377 | P30: =G30-B30 -> 0 | Q30: =N30-I30 -> 0
A31: ='DIA 02'!A31 -> ST-060 | O31: =C31+J31 -> 0 | P31: =G31-B31 -> 0 | Q31: =N31-I31 -> 0
A32: ='DIA 02'!A32 -> ST-53 | O32: =C32+J32 -> 0 | P32: =G32-B32 -> 0 | Q32: =N32-I32 -> 0
A33: ='DIA 02'!A33 -> ST-039 | B33: 9410.1 | C33: 251 | D33: CARLOS | E33: CESAR | F33: JESUS | I33: 9418 | J33: 223 | K33: MISAEL | L33: LUIS | M33: ROBERTO | O33: =C33+J33 -> 474 | P33: =G33-B33 -> -9410.1 | Q33: =N33-I33 -> -9418
A34: ='DIA 02'!A34 -> JL-025 | I34: 4161 | J34: 47 | K34: LEONEL | L34: LUIS | M34: ROBERTO | O34: =C34+J34 -> 47 | P34: =G34-B34 -> 0 | Q34: =N34-I34 -> -4161
A35: TOTALES | C35: =SUM(C7:C34) -> 682 | J35: =SUM(J7:J34) -> 1126 | O35: =C35+J35 -> 1808
A43: NOMBRE Y FIRMA DE QUIEN AUTORIZA | G43: NOMBRE Y FIRMA DE ALMACEN | O43: ADMINISTRADOR
P45: 44237 | R45: 44244 | T45: 44251
O46: ACEITE | P46: TAMBO | Q46: LTS | R46: TAMBO | S46: LTS | T46: TAMBO | U46: LTS
O47: HIDRAULICO | P47: 3 | R47: 2 | S47: 140 | T47: 0 | U47: 155
O48: MOTOR | P48: 3 | Q48: 70 | R48: 2 | S48: 182 | T48: 2 | U48: 170
O49: DIFERENCIAL | P49: 1 | Q49: 137 | R49: 1 | S49: 137 | T49: 1 | U49: 160
O50: MAQ.PERF. | P50: 2 | Q50: 117 | R50: 2 | S50: 27 | T50: 1 | U50: 150
...

Sheet DIA 04
B1: FECHA | E1: MGA CONTRATISTA MINERA S.A. DE C.V. | O1: ENTRADA DE DIESEL | P1: EXISTENCIA INICIAL DE DIESEL (LTS) | Q1: EXISTENCIA FINAL DE DIESEL (LTS)
B2: DIA | C2: MES | D2: AÑO | P2: ='DIA 03'!Q2+O2 -> 10367 | Q2: =P2-O35 -> 9086
A4: NO. DE EQUIPO | B4: PRIMER TURNO | I4: SEGUNDO TURNO
B6: Horometro Inicial 1ra | C6: DIESEL | D6: Nombre Operador | E6: Nombre Despachador | F6: Nombre del supervisor | G6: Horometro Final 1ra | I6: Horometro Inicial 2da | J6: =C6 -> DIESEL | K6: =D6 -> Nombre Operador | L6: =E6 -> Nombre Despachador | M6: =F6 -> Nombre del supervisor | N6: Horometro final 2da | O6: ='DIA 03'!O6 -> CONSUMO X DIA | P6: HRS 1ra | Q6: HRS 2da
A7: ='DIA 03'!A7 -> ST-031 (EPIROC 1030) | O7: =C7+J7 -> 0 | P7: =G7-B7 -> 0 | Q7: =N7-I7 -> 0
A8: ='DIA 03'!A8 -> ST-025 (1600) | O8: =C8+J8 -> 0 | P8: =G8-B8 -> 0 | Q8: =N8-I8 -> 0
A9: ='DIA 03'!A9 -> ST-036 R1300 | B9: 8960.6 | C9: 47 | D9: JESUS | E9: CESAR | F9: JESUS | I9: 89670 | J9: 128 | K9: JUAN | L9: LUIS | M9: ROBERTO | O9: =C9+J9 -> 175 | P9: =G9-B9 -> -8960.6 | Q9: =N9-I9 -> -89670
A10: ='DIA 03'!A10 -> ST-018 | B10: 9592 | C10: 168 | D10: RAUL | E10: CESAR | F10: JESUS | I10: 8599.9 | J10: 100 | K10: JUAN | L10: LUIS | M10: ROBERTO | O10: =C10+J10 -> 268 | P10: =G10-B10 -> -9592 | Q10: =N10-I10 -> -8599.9
A11: ='DIA 03'!A11 -> ST-034 KOMATSU | O11: =C11+J11 -> 0 | P11: =G11-B11 -> 0 | Q11: =N11-I11 -> 0
A12: ='DIA 03'!A12 -> JL-015 (DD311) | C12: 43 | D12: WIFREDO | E12: CESAR | F12: JESUS | O12: =C12+J12 -> 43 | P12: =G12-B12 -> 0 | Q12: =N12-I12 -> 0
A13: ='DIA 03'!A13 -> JL-019 | O13: =C13+J13 -> 0 | P13: =G13-B13 -> 0 | Q13: =N13-I13 -> 0
A14: ='DIA 03'!A14 -> JL-024 CANNON | O14: =C14+J14 -> 0 | P14: =G14-B14 -> 0 | Q14: =N14-I14 -> 0
A15: ='DIA 03'!A15 -> JA-007 RESEMIN | I15: 750.9 | J15: 30 | K15: CARLOS | L15: LUIS | M15: ROBERTO | O15: =C15+J15 -> 30 | P15: =G15-B15 -> 0 | Q15: =N15-I15 -> -750.9
A16: ='DIA 03'!A16 -> JA-004 CANNON | O16: =C16+J16 -> 0 | P16: =G16-B16 -> 0 | Q16: =N16-I16 -> 0
A17: ='DIA 03'!A17 -> RE-009 (RETROEXCAVADORA) | B17: 2759.6 | C17: 98 | D17: MARTIN | E17: CESAR | F17: JESUS | O17: =C17+J17 -> 98 | P17: =G17-B17 -> -2759.6 | Q17: =N17-I17 -> 0
A18: ='DIA 03'!A18 -> RE-010 (RETROEXCAVADORA) | O18: =C18+J18 -> 0 | P18: =G18-B18 -> 0 | Q18: =N18-I18 -> 0
A19: ='DIA 03'!A19 -> ZN | O19: =C19+J19 -> 0 | P19: =G19-B19 -> 0 | Q19: =N19-I19 -> 0
A20: ='DIA 03'!A20 -> CBP-001 (BAJO PERFIL) | O20: =C20+J20 -> 0 | P20: =G20-B20 -> 0 | Q20: =N20-I20 -> 0
A21: ='DIA 03'!A21 -> MG-105 | O21: =C21+J21 -> 0 | P21: =G21-B21 -> 0 | Q21: =N21-I21 -> 0
A22: ='DIA 03'!A22 -> MG-044 | J22: 102 | K22: MIGUEL | L22: LUIS | M22: ROBERTO | O22: =C22+J22 -> 102 | P22: =G22-B22 -> 0 | Q22: =N22-I22 -> 0
A23: ='DIA 03'!A23 -> MG-085 (POLVORERA) | O23: =C23+J23 -> 0 | P23: =G23-B23 -> 0 | Q23: =N23-I23 -> 0
A24: ='DIA 03'!A24 -> MG-033 (PERSONAL) | B24: 71434 | C24: 40 | D24: PAYAN | E24: CESAR | F24: JESUS | O24: =C24+J24 -> 40 | P24: =G24-B24 -> -71434 | Q24: =N24-I24 -> 0
A25: ='DIA 03'!A25 -> MG-113 | O25: =C25+J25 -> 0 | P25: =G25-B25 -> 0 | Q25: =N25-I25 -> 0
A26: ='DIA 03'!A26 -> MG-121 | B26: 25366 | C26: 52 | D26: PAYAN | E26: CESAR | F26: JESUS | O26: =C26+J26 -> 52 | P26: =G26-B26 -> -25366 | Q26: =N26-I26 -> 0
A27: ='DIA 03'!A27 -> MG-086 | O27: =C27+J27 -> 0 | P27: =G27-B27 -> 0 | Q27: =N27-I27 -> 0
A28: ='DIA 03'!A28 -> MG-111 | O28: =C28+J28 -> 0 | P28: =G28-B28 -> 0 | Q28: =N28-I28 -> 0
A29: ='DIA 03'!A29 -> MG-120 | O29: =C29+J29 -> 0 | P29: =G29-B29 -> 0 | Q29: =N29-I29 -> 0
A30: ='DIA 03'!A30 -> PROSERMIN | C30: 247 | J30: 138 | O30: =C30+J30 -> 385 | P30: =G30-B30 -> 0 | Q30: =N30-I30 -> 0
A31: ='DIA 03'!A31 -> ST-060 | O31: =C31+J31 -> 0 | P31: =G31-B31 -> 0 | Q31: =N31-I31 -> 0
A32: ='DIA 03'!A32 -> ST-53 | O32: =C32+J32 -> 0 | P32: =G32-B32 -> 0 | Q32: =N32-I32 -> 0
A33: ='DIA 03'!A33 -> ST-039 | B33: 9421 | C33: 88 | D33: CARLOS | E33: CESAR | F33: JESUS | O33: =C33+J33 -> 88 | P33: =G33-B33 -> -9421 | Q33: =N33-I33 -> 0
A34: ='DIA 03'!A34 -> JL-025 | O34: =C34+J34 -> 0 | P34: =G34-B34 -> 0 | Q34: =N34-I34 -> 0
A35: TOTALES | C35: =SUM(C7:C34) -> 783 | J35: =SUM(J7:J34) -> 498 | O35: =C35+J35 -> 1281
A43: NOMBRE Y FIRMA DE QUIEN AUTORIZA | G43: NOMBRE Y FIRMA DE ALMACEN | O43: ADMINISTRADOR
P45: 44237 | R45: 44244 | T45: 44251
O46: ACEITE | P46: TAMBO | Q46: LTS | R46: TAMBO | S46: LTS | T46: TAMBO | U46: LTS
O47: HIDRAULICO | P47: 3 | R47: 2 | S47: 140 | T47: 0 | U47: 155
O48: MOTOR | P48: 3 | Q48: 70 | R48: 2 | S48: 182 | T48: 2 | U48: 170
O49: DIFERENCIAL | P49: 1 | Q49: 137 | R49: 1 | S49: 137 | T49: 1 | U49: 160
O50: MAQ.PERF. | P50: 2 | Q50: 117 | R50: 2 | S50: 27 | T50: 1 | U50: 150
...

Sheet DIA 05
B1: FECHA | E1: MGA CONTRATISTA MINERA S.A. DE C.V. | O1: ENTRADA DE DIESEL | P1: EXISTENCIA INICIAL DE DIESEL (LTS) | Q1: EXISTENCIA FINAL DE DIESEL (LTS)
B2: DIA | C2: MES | D2: AÑO | P2: ='DIA 04'!Q2+O2 -> 9086 | Q2: =P2-O35 -> 7903
A4: NO. DE EQUIPO | B4: PRIMER TURNO | I4: SEGUNDO TURNO
B6: Horometro Inicial 1ra | C6: DIESEL | D6: Nombre Operador | E6: Nombre Despachador | F6: Nombre del supervisor | G6: Horometro Final 1ra | I6: Horometro Inicial 2da | J6: =C6 -> DIESEL | K6: =D6 -> Nombre Operador | L6: =E6 -> Nombre Despachador | M6: =F6 -> Nombre del supervisor | N6: Horometro final 2da | O6: ='DIA 04'!O6 -> CONSUMO X DIA | P6: HRS 1ra | Q6: HRS 2da
A7: ='DIA 04'!A7 -> ST-031 (EPIROC 1030) | O7: =C7+J7 -> 0 | P7: =G7-B7 -> 0 | Q7: =N7-I7 -> 0
A8: ='DIA 04'!A8 -> ST-025 (1600) | O8: =C8+J8 -> 0 | P8: =G8-B8 -> 0 | Q8: =N8-I8 -> 0
A9: ='DIA 04'!A9 -> ST-036 R1300 | B9: 8971.8 | C9: 153 | D9: JESUS | E9: CESAR | F9: JESUS | I9: 8980 | J9: 94 | K9: JUAN | L9: LUIS | M9: ROBERTO | O9: =C9+J9 -> 247 | P9: =G9-B9 -> -8971.8 | Q9: =N9-I9 -> -8980
A10: ='DIA 04'!A10 -> ST-018 | O10: =C10+J10 -> 0 | P10: =G10-B10 -> 0 | Q10: =N10-I10 -> 0
A11: ='DIA 04'!A11 -> ST-034 KOMATSU | O11: =C11+J11 -> 0 | P11: =G11-B11 -> 0 | Q11: =N11-I11 -> 0
A12: ='DIA 04'!A12 -> JL-015 (DD311) | O12: =C12+J12 -> 0 | P12: =G12-B12 -> 0 | Q12: =N12-I12 -> 0
A13: ='DIA 04'!A13 -> JL-019 | O13: =C13+J13 -> 0 | P13: =G13-B13 -> 0 | Q13: =N13-I13 -> 0
A14: ='DIA 04'!A14 -> JL-024 CANNON | O14: =C14+J14 -> 0 | P14: =G14-B14 -> 0 | Q14: =N14-I14 -> 0
A15: ='DIA 04'!A15 -> JA-007 RESEMIN | O15: =C15+J15 -> 0 | P15: =G15-B15 -> 0 | Q15: =N15-I15 -> 0
A16: ='DIA 04'!A16 -> JA-004 CANNON | O16: =C16+J16 -> 0 | P16: =G16-B16 -> 0 | Q16: =N16-I16 -> 0
A17: ='DIA 04'!A17 -> RE-009 (RETROEXCAVADORA) | I17: 6628.4 | J17: 91 | K17: FRANCISCO | L17: LUIS | M17: ROBERTO | O17: =C17+J17 -> 91 | P17: =G17-B17 -> 0 | Q17: =N17-I17 -> -6628.4
A18: ='DIA 04'!A18 -> RE-010 (RETROEXCAVADORA) | O18: =C18+J18 -> 0 | P18: =G18-B18 -> 0 | Q18: =N18-I18 -> 0
A19: ='DIA 04'!A19 -> ZN | O19: =C19+J19 -> 0 | P19: =G19-B19 -> 0 | Q19: =N19-I19 -> 0
A20: ='DIA 04'!A20 -> CBP-001 (BAJO PERFIL) | O20: =C20+J20 -> 0 | P20: =G20-B20 -> 0 | Q20: =N20-I20 -> 0
A21: ='DIA 04'!A21 -> MG-105 | O21: =C21+J21 -> 0 | P21: =G21-B21 -> 0 | Q21: =N21-I21 -> 0
A22: ='DIA 04'!A22 -> MG-044 | O22: =C22+J22 -> 0 | P22: =G22-B22 -> 0 | Q22: =N22-I22 -> 0
A23: ='DIA 04'!A23 -> MG-085 (POLVORERA) | O23: =C23+J23 -> 0 | P23: =G23-B23 -> 0 | Q23: =N23-I23 -> 0
A24: ='DIA 04'!A24 -> MG-033 (PERSONAL) | O24: =C24+J24 -> 0 | P24: =G24-B24 -> 0 | Q24: =N24-I24 -> 0
A25: ='DIA 04'!A25 -> MG-113 | O25: =C25+J25 -> 0 | P25: =G25-B25 -> 0 | Q25: =N25-I25 -> 0
A26: ='DIA 04'!A26 -> MG-121 | B26: 25397 | C26: 5 | D26: REYNALDO | O26: =C26+J26 -> 5 | P26: =G26-B26 -> -25397 | Q26: =N26-I26 -> 0
A27: ='DIA 04'!A27 -> MG-086 | O27: =C27+J27 -> 0 | P27: =G27-B27 -> 0 | Q27: =N27-I27 -> 0
A28: ='DIA 04'!A28 -> MG-111 | O28: =C28+J28 -> 0 | P28: =G28-B28 -> 0 | Q28: =N28-I28 -> 0
A29: ='DIA 04'!A29 -> MG-120 | O29: =C29+J29 -> 0 | P29: =G29-B29 -> 0 | Q29: =N29-I29 -> 0
A30: ='DIA 04'!A30 -> PROSERMIN | C30: 270 | J30: 290 | O30: =C30+J30 -> 560 | P30: =G30-B30 -> 0 | Q30: =N30-I30 -> 0
A31: ='DIA 04'!A31 -> ST-060 | O31: =C31+J31 -> 0 | P31: =G31-B31 -> 0 | Q31: =N31-I31 -> 0
A32: ='DIA 04'!A32 -> ST-53 | O32: =C32+J32 -> 0 | P32: =G32-B32 -> 0 | Q32: =N32-I32 -> 0
A33: ='DIA 04'!A33 -> ST-039 | B33: 960418 | C33: 146 | D33: RAUL | E33: CESAR | F33: JESUS | I33: 9609 | J33: 134 | K33: MISAEL | L33: LUIS | M33: ROBERTO | O33: =C33+J33 -> 280 | P33: =G33-B33 -> -960418 | Q33: =N33-I33 -> -9609
A34: ='DIA 04'!A34 -> JL-025 | O34: =C34+J34 -> 0 | P34: =G34-B34 -> 0 | Q34: =N34-I34 -> 0
A35: TOTALES | C35: =SUM(C7:C34) -> 574 | J35: =SUM(J7:J34) -> 609 | O35: =C35+J35 -> 1183
A43: NOMBRE Y FIRMA DE QUIEN AUTORIZA | G43: NOMBRE Y FIRMA DE ALMACEN | O43: ADMINISTRADOR
P45: 44237 | R45: 44244 | T45: 44251
O46: ACEITE | P46: TAMBO | Q46: LTS | R46: TAMBO | S46: LTS | T46: TAMBO | U46: LTS
O47: HIDRAULICO | P47: 3 | R47: 2 | S47: 140 | T47: 0 | U47: 155
O48: MOTOR | P48: 3 | Q48: 70 | R48: 2 | S48: 182 | T48: 2 | U48: 170
O49: DIFERENCIAL | P49: 1 | Q49: 137 | R49: 1 | S49: 137 | T49: 1 | U49: 160
O50: MAQ.PERF. | P50: 2 | Q50: 117 | R50: 2 | S50: 27 | T50: 1 | U50: 150
...

Sheet DIA 06
B1: FECHA | E1: MGA CONTRATISTA MINERA S.A. DE C.V. | O1: ENTRADA DE DIESEL | P1: EXISTENCIA INICIAL DE DIESEL (LTS) | Q1: EXISTENCIA FINAL DE DIESEL (LTS)
B2: DIA | C2: MES | D2: AÑO | O2: 2191 | P2: ='DIA 05'!Q2+O2 -> 10094 | Q2: =P2-O35 -> 8518
A4: NO. DE EQUIPO | B4: PRIMER TURNO | I4: SEGUNDO TURNO
B6: Horometro Inicial 1ra | C6: DIESEL | D6: Nombre Operador | E6: Nombre Despachador | F6: Nombre del supervisor | G6: Horometro Final 1ra | I6: Horometro Inicial 2da | J6: =C6 -> DIESEL | K6: =D6 -> Nombre Operador | L6: =E6 -> Nombre Despachador | M6: =F6 -> Nombre del supervisor | N6: Horometro final 2da | O6: ='DIA 05'!O6 -> CONSUMO X DIA | P6: HRS 1ra | Q6: HRS 2da
A7: ='DIA 05'!A7 -> ST-031 (EPIROC 1030) | B7: 4862.7 | C7: 248 | D7: CARLOS | E7: CESAR | F7: JESUS | O7: =C7+J7 -> 248 | P7: =G7-B7 -> -4862.7 | Q7: =N7-I7 -> 0
A8: ='DIA 05'!A8 -> ST-025 (1600) | O8: =C8+J8 -> 0 | P8: =G8-B8 -> 0 | Q8: =N8-I8 -> 0
A9: ='DIA 05'!A9 -> ST-036 R1300 | B9: 8987.5 | C9: 160 | D9: JESUS | E9: CESAR | F9: JESUS | I9: 8996.8 | J9: 155 | K9: JUAN | L9: LUIS | M9: ROBERTO | O9: =C9+J9 -> 315 | P9: =G9-B9 -> -8987.5 | Q9: =N9-I9 -> -8996.8
A10: ='DIA 05'!A10 -> ST-018 | B10: 9616 | C10: 108 | D10: RAUL | E10: CESAR | F10: JESUS | I10: 9621 | J10: 101 | K10: MISAEL | L10: LUIS | M10: ROBERTO | O10: =C10+J10 -> 209 | P10: =G10-B10 -> -9616 | Q10: =N10-I10 -> -9621
A11: ='DIA 05'!A11 -> ST-034 KOMATSU | O11: =C11+J11 -> 0 | P11: =G11-B11 -> 0 | Q11: =N11-I11 -> 0
A12: ='DIA 05'!A12 -> JL-015 (DD311) | C12: 36 | D12: WILFREDO | E12: CESAR | F12: JESUS | O12: =C12+J12 -> 36 | P12: =G12-B12 -> 0 | Q12: =N12-I12 -> 0
A13: ='DIA 05'!A13 -> JL-019 | O13: =C13+J13 -> 0 | P13: =G13-B13 -> 0 | Q13: =N13-I13 -> 0
A14: ='DIA 05'!A14 -> JL-024 CANNON | O14: =C14+J14 -> 0 | P14: =G14-B14 -> 0 | Q14: =N14-I14 -> 0
A15: ='DIA 05'!A15 -> JA-007 RESEMIN | O15: =C15+J15 -> 0 | P15: =G15-B15 -> 0 | Q15: =N15-I15 -> 0
A16: ='DIA 05'!A16 -> JA-004 CANNON | O16: =C16+J16 -> 0 | P16: =G16-B16 -> 0 | Q16: =N16-I16 -> 0
A17: ='DIA 05'!A17 -> RE-009 (RETROEXCAVADORA) | I17: 6645.3 | J17: 59 | K17: FRANCISCO | L17: LUIS | M17: ROBERTO | O17: =C17+J17 -> 59 | P17: =G17-B17 -> 0 | Q17: =N17-I17 -> -6645.3
A18: ='DIA 05'!A18 -> RE-010 (RETROEXCAVADORA) | B18: 2779.6 | C18: 81 | D18: ADRIAN | E18: CESAR | F18: JESUS | O18: =C18+J18 -> 81 | P18: =G18-B18 -> -2779.6 | Q18: =N18-I18 -> 0
A19: ='DIA 05'!A19 -> ZN | O19: =C19+J19 -> 0 | P19: =G19-B19 -> 0 | Q19: =N19-I19 -> 0
A20: ='DIA 05'!A20 -> CBP-001 (BAJO PERFIL) | O20: =C20+J20 -> 0 | P20: =G20-B20 -> 0 | Q20: =N20-I20 -> 0
A21: ='DIA 05'!A21 -> MG-105 | O21: =C21+J21 -> 0 | P21: =G21-B21 -> 0 | Q21: =N21-I21 -> 0
A22: ='DIA 05'!A22 -> MG-044 | I22: 95276 | J22: 98 | K22: MIGUEL | L22: LUIS | M22: ROBERTO | O22: =C22+J22 -> 98 | P22: =G22-B22 -> 0 | Q22: =N22-I22 -> -95276
A23: ='DIA 05'!A23 -> MG-085 (POLVORERA) | O23: =C23+J23 -> 0 | P23: =G23-B23 -> 0 | Q23: =N23-I23 -> 0
A24: ='DIA 05'!A24 -> MG-033 (PERSONAL) | B24: 71434 | C24: 45 | D24: PAYAN | E24: CESAR | F24: JESUS | O24: =C24+J24 -> 45 | P24: =G24-B24 -> -71434 | Q24: =N24-I24 -> 0
A25: ='DIA 05'!A25 -> MG-113 | O25: =C25+J25 -> 0 | P25: =G25-B25 -> 0 | Q25: =N25-I25 -> 0
A26: ='DIA 05'!A26 -> MG-121 | O26: =C26+J26 -> 0 | P26: =G26-B26 -> 0 | Q26: =N26-I26 -> 0
A27: ='DIA 05'!A27 -> MG-086 | O27: =C27+J27 -> 0 | P27: =G27-B27 -> 0 | Q27: =N27-I27 -> 0
A28: ='DIA 05'!A28 -> MG-111 | O28: =C28+J28 -> 0 | P28: =G28-B28 -> 0 | Q28: =N28-I28 -> 0
A29: ='DIA 05'!A29 -> MG-120 | O29: =C29+J29 -> 0 | P29: =G29-B29 -> 0 | Q29: =N29-I29 -> 0
A30: ='DIA 05'!A30 -> PROSERMIN | C30: 228 | J30: 257 | O30: =C30+J30 -> 485 | P30: =G30-B30 -> 0 | Q30: =N30-I30 -> 0
A31: ='DIA 05'!A31 -> ST-060 | O31: =C31+J31 -> 0 | P31: =G31-B31 -> 0 | Q31: =N31-I31 -> 0
A32: ='DIA 05'!A32 -> ST-53 | O32: =C32+J32 -> 0 | P32: =G32-B32 -> 0 | Q32: =N32-I32 -> 0
A33: ='DIA 05'!A33 -> ST-039 | O33: =C33+J33 -> 0 | P33: =G33-B33 -> 0 | Q33: =N33-I33 -> 0
A34: ='DIA 05'!A34 -> JL-025 | O34: =C34+J34 -> 0 | P34: =G34-B34 -> 0 | Q34: =N34-I34 -> 0
A35: TOTALES | C35: =SUM(C7:C34) -> 906 | J35: =SUM(J7:J34) -> 670 | O35: =C35+J35 -> 1576
A43: NOMBRE Y FIRMA DE QUIEN AUTORIZA | G43: NOMBRE Y FIRMA DE ALMACEN | O43: ADMINISTRADOR
P45: 44237 | R45: 44244 | T45: 44251
O46: ACEITE | P46: TAMBO | Q46: LTS | R46: TAMBO | S46: LTS | T46: TAMBO | U46: LTS
O47: HIDRAULICO | P47: 3 | R47: 2 | S47: 140 | T47: 0 | U47: 155
O48: MOTOR | P48: 3 | Q48: 70 | R48: 2 | S48: 182 | T48: 2 | U48: 170
O49: DIFERENCIAL | P49: 1 | Q49: 137 | R49: 1 | S49: 137 | T49: 1 | U49: 160
O50: MAQ.PERF. | P50: 2 | Q50: 117 | R50: 2 | S50: 27 | T50: 1 | U50: 150
...

Sheet DIA 07
B1: FECHA | E1: MGA CONTRATISTA MINERA S.A. DE C.V. | O1: ENTRADA DE DIESEL | P1: EXISTENCIA INICIAL DE DIESEL (LTS) | Q1: EXISTENCIA FINAL DE DIESEL (LTS)
B2: DIA | C2: MES | D2: AÑO | P2: ='DIA 06'!Q2+O2 -> 8518 | Q2: =P2-O35 -> 7363
A4: NO. DE EQUIPO | B4: PRIMER TURNO | I4: SEGUNDO TURNO
B6: Horometro Inicial 1ra | C6: DIESEL | D6: Nombre Operador | E6: Nombre Despachador | F6: Nombre del supervisor | G6: Horometro Final 1ra | I6: Horometro Inicial 2da | J6: =C6 -> DIESEL | K6: =D6 -> Nombre Operador | L6: =E6 -> Nombre Despachador | M6: =F6 -> Nombre del supervisor | N6: Horometro final 2da | O6: ='DIA 06'!O6 -> CONSUMO X DIA | P6: HRS 1ra | Q6: HRS 2da
A7: ='DIA 06'!A7 -> ST-031 (EPIROC 1030) | O7: =C7+J7 -> 0 | P7: =G7-B7 -> 0 | Q7: =N7-I7 -> 0
A8: ='DIA 06'!A8 -> ST-025 (1600) | O8: =C8+J8 -> 0 | P8: =G8-B8 -> 0 | Q8: =N8-I8 -> 0
A9: ='DIA 06'!A9 -> ST-036 R1300 | B9: 9005.1 | C9: 213 | D9: OÑATE | E9: JOSE | F9: MANUEL | I9: 9012.6 | J9: 108 | K9: JESUS | L9: CESAR | M9: JESUS | O9: =C9+J9 -> 321 | P9: =G9-B9 -> -9005.1 | Q9: =N9-I9 -> -9012.6
A10: ='DIA 06'!A10 -> ST-018 | B10: 9629.2 | C10: 206 | D10: TONY | E10: JOSE | F10: MANUEL | I10: 9638.6 | J10: 187 | K10: CARLOS | L10: CESAR | M10: JESUS | O10: =C10+J10 -> 393 | P10: =G10-B10 -> -9629.2 | Q10: =N10-I10 -> -9638.6
A11: ='DIA 06'!A11 -> ST-034 KOMATSU | O11: =C11+J11 -> 0 | P11: =G11-B11 -> 0 | Q11: =N11-I11 -> 0
A12: ='DIA 06'!A12 -> JL-015 (DD311) | O12: =C12+J12 -> 0 | P12: =G12-B12 -> 0 | Q12: =N12-I12 -> 0
A13: ='DIA 06'!A13 -> JL-019 | O13: =C13+J13 -> 0 | P13: =G13-B13 -> 0 | Q13: =N13-I13 -> 0
A14: ='DIA 06'!A14 -> JL-024 CANNON | O14: =C14+J14 -> 0 | P14: =G14-B14 -> 0 | Q14: =N14-I14 -> 0
A15: ='DIA 06'!A15 -> JA-007 RESEMIN | I15: 751.1 | J15: 30 | K15: HILARIO | L15: CESAR | M15: JESUS | O15: =C15+J15 -> 30 | P15: =G15-B15 -> 0 | Q15: =N15-I15 -> -751.1
A16: ='DIA 06'!A16 -> JA-004 CANNON | O16: =C16+J16 -> 0 | P16: =G16-B16 -> 0 | Q16: =N16-I16 -> 0
A17: ='DIA 06'!A17 -> RE-009 (RETROEXCAVADORA) | B17: 6651.7 | C17: 13 | D17: CRISTIAN | E17: JOSE | F17: MANUEL | O17: =C17+J17 -> 13 | P17: =G17-B17 -> -6651.7 | Q17: =N17-I17 -> 0
A18: ='DIA 06'!A18 -> RE-010 (RETROEXCAVADORA) | O18: =C18+J18 -> 0 | P18: =G18-B18 -> 0 | Q18: =N18-I18 -> 0
A19: ='DIA 06'!A19 -> ZN | O19: =C19+J19 -> 0 | P19: =G19-B19 -> 0 | Q19: =N19-I19 -> 0
A20: ='DIA 06'!A20 -> CBP-001 (BAJO PERFIL) | O20: =C20+J20 -> 0 | P20: =G20-B20 -> 0 | Q20: =N20-I20 -> 0
A21: ='DIA 06'!A21 -> MG-105 | O21: =C21+J21 -> 0 | P21: =G21-B21 -> 0 | Q21: =N21-I21 -> 0
A22: ='DIA 06'!A22 -> MG-044 | O22: =C22+J22 -> 0 | P22: =G22-B22 -> 0 | Q22: =N22-I22 -> 0
A23: ='DIA 06'!A23 -> MG-085 (POLVORERA) | O23: =C23+J23 -> 0 | P23: =G23-B23 -> 0 | Q23: =N23-I23 -> 0
A24: ='DIA 06'!A24 -> MG-033 (PERSONAL) | O24: =C24+J24 -> 0 | P24: =G24-B24 -> 0 | Q24: =N24-I24 -> 0
A25: ='DIA 06'!A25 -> MG-113 | O25: =C25+J25 -> 0 | P25: =G25-B25 -> 0 | Q25: =N25-I25 -> 0
A26: ='DIA 06'!A26 -> MG-121 | O26: =C26+J26 -> 0 | P26: =G26-B26 -> 0 | Q26: =N26-I26 -> 0
A27: ='DIA 06'!A27 -> MG-086 | O27: =C27+J27 -> 0 | P27: =G27-B27 -> 0 | Q27: =N27-I27 -> 0
A28: ='DIA 06'!A28 -> MG-111 | O28: =C28+J28 -> 0 | P28: =G28-B28 -> 0 | Q28: =N28-I28 -> 0
A29: ='DIA 06'!A29 -> MG-120 | O29: =C29+J29 -> 0 | P29: =G29-B29 -> 0 | Q29: =N29-I29 -> 0
A30: ='DIA 06'!A30 -> PROSERMIN | C30: 183 | J30: 173 | O30: =C30+J30 -> 356 | P30: =G30-B30 -> 0 | Q30: =N30-I30 -> 0
A31: ='DIA 06'!A31 -> ST-060 | O31: =C31+J31 -> 0 | P31: =G31-B31 -> 0 | Q31: =N31-I31 -> 0
A32: ='DIA 06'!A32 -> ST-53 | O32: =C32+J32 -> 0 | P32: =G32-B32 -> 0 | Q32: =N32-I32 -> 0
A33: ='DIA 06'!A33 -> ST-039 | O33: =C33+J33 -> 0 | P33: =G33-B33 -> 0 | Q33: =N33-I33 -> 0
A34: ='DIA 06'!A34 -> JL-025 | B34: 4169.6 | C34: 42 | D34: NATIVIDAD | E34: JOSE | F34: MANUEL | O34: =C34+J34 -> 42 | P34: =G34-B34 -> -4169.6 | Q34: =N34-I34 -> 0
A35: TOTALES | C35: =SUM(C7:C34) -> 657 | J35: =SUM(J7:J34) -> 498 | O35: =C35+J35 -> 1155
A43: NOMBRE Y FIRMA DE QUIEN AUTORIZA | G43: NOMBRE Y FIRMA DE ALMACEN | O43: ADMINISTRADOR
P45: 44237 | R45: 44244 | T45: 44251
O46: ACEITE | P46: TAMBO | Q46: LTS | R46: TAMBO | S46: LTS | T46: TAMBO | U46: LTS
O47: HIDRAULICO | P47: 3 | R47: 2 | S47: 140 | T47: 0 | U47: 155
O48: MOTOR | P48: 3 | Q48: 70 | R48: 2 | S48: 182 | T48: 2 | U48: 170
O49: DIFERENCIAL | P49: 1 | Q49: 137 | R49: 1 | S49: 137 | T49: 1 | U49: 160
O50: MAQ.PERF. | P50: 2 | Q50: 117 | R50: 2 | S50: 27 | T50: 1 | U50: 150
...

Sheet DIA 08
B1: FECHA | E1: MGA CONTRATISTA MINERA S.A. DE C.V. | O1: ENTRADA DE DIESEL | P1: EXISTENCIA INICIAL DE DIESEL (LTS) | Q1: EXISTENCIA FINAL DE DIESEL (LTS)
B2: DIA | C2: MES | D2: AÑO | O2: 1750 | P2: ='DIA 07'!Q2+O2 -> 9113 | Q2: =P2-O35 -> 7840
A4: NO. DE EQUIPO | B4: PRIMER TURNO | I4: SEGUNDO TURNO
B6: Horometro Inicial 1ra | C6: DIESEL | D6: Nombre Operador | E6: Nombre Despachador | F6: Nombre del supervisor | G6: Horometro Final 1ra | I6: Horometro Inicial 2da | J6: =C6 -> DIESEL | K6: =D6 -> Nombre Operador | L6: =E6 -> Nombre Despachador | M6: =F6 -> Nombre del supervisor | N6: Horometro final 2da | O6: ='DIA 07'!O6 -> CONSUMO X DIA | P6: HRS 1ra | Q6: HRS 2da
A7: ='DIA 07'!A7 -> ST-031 (EPIROC 1030) | O7: =C7+J7 -> 0 | P7: =G7-B7 -> 0 | Q7: =N7-I7 -> 0
A8: ='DIA 07'!A8 -> ST-025 (1600) | O8: =C8+J8 -> 0 | P8: =G8-B8 -> 0 | Q8: =N8-I8 -> 0
A9: ='DIA 07'!A9 -> ST-036 R1300 | B9: 9021.9 | C9: 186 | D9: OÑETE | E9: JOSE | F9: MANUEL | I9: 9031.2 | J9: 149 | K9: JESUS | L9: CESAR | M9: JESUS | O9: =C9+J9 -> 335 | P9: =G9-B9 -> -9021.9 | Q9: =N9-I9 -> -9031.2
A10: ='DIA 07'!A10 -> ST-018 | B10: 9647 | C10: 156 | D10: TONY | E10: JOSE | F10: MANUEL | I10: 9657.4 | J10: 136 | K10: CARLOS | L10: CESAR | M10: JESUS | O10: =C10+J10 -> 292 | P10: =G10-B10 -> -9647 | Q10: =N10-I10 -> -9657.4
A11: ='DIA 07'!A11 -> ST-034 KOMATSU | O11: =C11+J11 -> 0 | P11: =G11-B11 -> 0 | Q11: =N11-I11 -> 0
A12: ='DIA 07'!A12 -> JL-015 (DD311) | O12: =C12+J12 -> 0 | P12: =G12-B12 -> 0 | Q12: =N12-I12 -> 0
A13: ='DIA 07'!A13 -> JL-019 | O13: =C13+J13 -> 0 | P13: =G13-B13 -> 0 | Q13: =N13-I13 -> 0
A14: ='DIA 07'!A14 -> JL-024 CANNON | O14: =C14+J14 -> 0 | P14: =G14-B14 -> 0 | Q14: =N14-I14 -> 0
A15: ='DIA 07'!A15 -> JA-007 RESEMIN | O15: =C15+J15 -> 0 | P15: =G15-B15 -> 0 | Q15: =N15-I15 -> 0
A16: ='DIA 07'!A16 -> JA-004 CANNON | B16: 2397.4 | C16: 118 | D16: ANTONIO | E16: JOSE | F16: MANUEL | O16: =C16+J16 -> 118 | P16: =G16-B16 -> -2397.4 | Q16: =N16-I16 -> 0
A17: ='DIA 07'!A17 -> RE-009 (RETROEXCAVADORA) | B17: 6666 | C17: 71 | D17: RAFAEL | E17: JOSE | F17: MANUEL | O17: =C17+J17 -> 71 | P17: =G17-B17 -> -6666 | Q17: =N17-I17 -> 0
A18: ='DIA 07'!A18 -> RE-010 (RETROEXCAVADORA) | B18: 2798 | C18: 89 | D18: CRISTIAN | E18: JOSE | F18: MANUEL | O18: =C18+J18 -> 89 | P18: =G18-B18 -> -2798 | Q18: =N18-I18 -> 0
A19: ='DIA 07'!A19 -> ZN | O19: =C19+J19 -> 0 | P19: =G19-B19 -> 0 | Q19: =N19-I19 -> 0
A20: ='DIA 07'!A20 -> CBP-001 (BAJO PERFIL) | O20: =C20+J20 -> 0 | P20: =G20-B20 -> 0 | Q20: =N20-I20 -> 0
A21: ='DIA 07'!A21 -> MG-105 | O21: =C21+J21 -> 0 | P21: =G21-B21 -> 0 | Q21: =N21-I21 -> 0
A22: ='DIA 07'!A22 -> MG-044 | O22: =C22+J22 -> 0 | P22: =G22-B22 -> 0 | Q22: =N22-I22 -> 0
A23: ='DIA 07'!A23 -> MG-085 (POLVORERA) | O23: =C23+J23 -> 0 | P23: =G23-B23 -> 0 | Q23: =N23-I23 -> 0
A24: ='DIA 07'!A24 -> MG-033 (PERSONAL) | O24: =C24+J24 -> 0 | P24: =G24-B24 -> 0 | Q24: =N24-I24 -> 0
A25: ='DIA 07'!A25 -> MG-113 | O25: =C25+J25 -> 0 | P25: =G25-B25 -> 0 | Q25: =N25-I25 -> 0
A26: ='DIA 07'!A26 -> MG-121 | B26: 25940 | C26: 68 | D26: MIGUEL | E26: JOSE | F26: MANUEL | O26: =C26+J26 -> 68 | P26: =G26-B26 -> -25940 | Q26: =N26-I26 -> 0
A27: ='DIA 07'!A27 -> MG-086 | O27: =C27+J27 -> 0 | P27: =G27-B27 -> 0 | Q27: =N27-I27 -> 0
A28: ='DIA 07'!A28 -> MG-111 | O28: =C28+J28 -> 0 | P28: =G28-B28 -> 0 | Q28: =N28-I28 -> 0
A29: ='DIA 07'!A29 -> MG-120 | O29: =C29+J29 -> 0 | P29: =G29-B29 -> 0 | Q29: =N29-I29 -> 0
A30: ='DIA 07'!A30 -> PROSERMIN | C30: 102 | J30: 198 | O30: =C30+J30 -> 300 | P30: =G30-B30 -> 0 | Q30: =N30-I30 -> 0
A31: ='DIA 07'!A31 -> ST-060 | O31: =C31+J31 -> 0 | P31: =G31-B31 -> 0 | Q31: =N31-I31 -> 0
A32: ='DIA 07'!A32 -> ST-53 | O32: =C32+J32 -> 0 | P32: =G32-B32 -> 0 | Q32: =N32-I32 -> 0
A33: ='DIA 07'!A33 -> ST-039 | O33: =C33+J33 -> 0 | P33: =G33-B33 -> 0 | Q33: =N33-I33 -> 0
A34: ='DIA 07'!A34 -> JL-025 | O34: =C34+J34 -> 0 | P34: =G34-B34 -> 0 | Q34: =N34-I34 -> 0
A35: TOTALES | C35: =SUM(C7:C34) -> 790 | J35: =SUM(J7:J34) -> 483 | O35: =C35+J35 -> 1273
A43: NOMBRE Y FIRMA DE QUIEN AUTORIZA | G43: NOMBRE Y FIRMA DE ALMACEN | O43: ADMINISTRADOR
P45: 44237 | R45: 44244 | T45: 44251
O46: ACEITE | P46: TAMBO | Q46: LTS | R46: TAMBO | S46: LTS | T46: TAMBO | U46: LTS
O47: HIDRAULICO | P47: 3 | R47: 2 | S47: 140 | T47: 0 | U47: 155
O48: MOTOR | P48: 3 | Q48: 70 | R48: 2 | S48: 182 | T48: 2 | U48: 170
O49: DIFERENCIAL | P49: 1 | Q49: 137 | R49: 1 | S49: 137 | T49: 1 | U49: 160
O50: MAQ.PERF. | P50: 2 | Q50: 117 | R50: 2 | S50: 27 | T50: 1 | U50: 150
...

Sheet DIA 09
B1: FECHA | E1: MGA CONTRATISTA MINERA S.A. DE C.V. | O1: ENTRADA DE DIESEL | P1: EXISTENCIA INICIAL DE DIESEL (LTS) | Q1: EXISTENCIA FINAL DE DIESEL (LTS)
B2: DIA | C2: MES | D2: AÑO | P2: ='DIA 08'!Q2+O2 -> 7840 | Q2: =P2-O35 -> 6537
A4: NO. DE EQUIPO | B4: PRIMER TURNO | I4: SEGUNDO TURNO
B6: Horometro Inicial 1ra | C6: DIESEL | D6: Nombre Operador | E6: Nombre Despachador | F6: Nombre del supervisor | G6: Horometro Final 1ra | I6: Horometro Inicial 2da | J6: =C6 -> DIESEL | K6: =D6 -> Nombre Operador | L6: =E6 -> Nombre Despachador | M6: =F6 -> Nombre del supervisor | N6: Horometro final 2da | O6: ='DIA 08'!O6 -> CONSUMO X DIA | P6: HRS 1ra | Q6: HRS 2da
A7: ='DIA 08'!A7 -> ST-031 (EPIROC 1030) | O7: =J7+C7 -> 0 | P7: =G7-B7 -> 0 | Q7: =N7-I7 -> 0
A8: ='DIA 08'!A8 -> ST-025 (1600) | O8: =J8+C8 -> 0 | P8: =G8-B8 -> 0 | Q8: =N8-I8 -> 0
A9: ='DIA 08'!A9 -> ST-036 R1300 | B9: 9039.5 | C9: 153 | D9: OÑATE | E9: JOSE | F9: MANUEL | I9: 9047.2 | J9: 117 | K9: JESUS | L9: CESAR | M9: JESUS | O9: =J9+C9 -> 270 | P9: =G9-B9 -> -9039.5 | Q9: =N9-I9 -> -9047.2
A10: ='DIA 08'!A10 -> ST-018 | B10: 9659.4 | C10: 175 | D10: TONY | E10: JOSE | F10: MANUEL | I10: 9666.5 | J10: 173 | K10: 173 | L10: CESAR | M10: JESUS | O10: =J10+C10 -> 348 | P10: =G10-B10 -> -9659.4 | Q10: =N10-I10 -> -9666.5
A11: ='DIA 08'!A11 -> ST-034 KOMATSU | O11: =J11+C11 -> 0 | P11: =G11-B11 -> 0 | Q11: =N11-I11 -> 0
A12: ='DIA 08'!A12 -> JL-015 (DD311) | C12: 37 | D12: SERGIO | E12: JOSE | F12: MANUEL | O12: =J12+C12 -> 37 | P12: =G12-B12 -> 0 | Q12: =N12-I12 -> 0
A13: ='DIA 08'!A13 -> JL-019 | O13: =J13+C13 -> 0 | P13: =G13-B13 -> 0 | Q13: =N13-I13 -> 0
A14: ='DIA 08'!A14 -> JL-024 CANNON | O14: =J14+C14 -> 0 | P14: =G14-B14 -> 0 | Q14: =N14-I14 -> 0
A15: ='DIA 08'!A15 -> JA-007 RESEMIN | O15: =J15+C15 -> 0 | P15: =G15-B15 -> 0 | Q15: =N15-I15 -> 0
A16: ='DIA 08'!A16 -> JA-004 CANNON | O16: =J16+C16 -> 0 | P16: =G16-B16 -> 0 | Q16: =N16-I16 -> 0
A17: ='DIA 08'!A17 -> RE-009 (RETROEXCAVADORA) | O17: =J17+C17 -> 0 | P17: =G17-B17 -> 0 | Q17: =N17-I17 -> 0
A18: ='DIA 08'!A18 -> RE-010 (RETROEXCAVADORA) | I18: 6681 | J18: 58 | K18: ADRIAN | L18: CESAR | M18: JESUS | O18: =J18+C18 -> 58 | P18: =G18-B18 -> 0 | Q18: =N18-I18 -> -6681
A19: ='DIA 08'!A19 -> ZN | O19: =J19+C19 -> 0 | P19: =G19-B19 -> 0 | Q19: =N19-I19 -> 0
A20: ='DIA 08'!A20 -> CBP-001 (BAJO PERFIL) | O20: =J20+C20 -> 0 | P20: =G20-B20 -> 0 | Q20: =N20-I20 -> 0
A21: ='DIA 08'!A21 -> MG-105 | B21: 3642.2 | C21: 333 | D21: GERMAN | E21: JOSE | F21: MANUEL | O21: =J21+C21 -> 333 | P21: =G21-B21 -> -3642.2 | Q21: =N21-I21 -> 0
A22: ='DIA 08'!A22 -> MG-044 | O22: =J22+C22 -> 0 | P22: =G22-B22 -> 0 | Q22: =N22-I22 -> 0
A23: ='DIA 08'!A23 -> MG-085 (POLVORERA) | O23: =J23+C23 -> 0 | P23: =G23-B23 -> 0 | Q23: =N23-I23 -> 0
A24: ='DIA 08'!A24 -> MG-033 (PERSONAL) | O24: =J24+C24 -> 0 | P24: =G24-B24 -> 0 | Q24: =N24-I24 -> 0
A25: ='DIA 08'!A25 -> MG-113 | O25: =J25+C25 -> 0 | P25: =G25-B25 -> 0 | Q25: =N25-I25 -> 0
A26: ='DIA 08'!A26 -> MG-121 | O26: =J26+C26 -> 0 | P26: =G26-B26 -> 0 | Q26: =N26-I26 -> 0
A27: ='DIA 08'!A27 -> MG-086 | O27: =J27+C27 -> 0 | P27: =G27-B27 -> 0 | Q27: =N27-I27 -> 0
A28: ='DIA 08'!A28 -> MG-111 | O28: =J28+C28 -> 0 | P28: =G28-B28 -> 0 | Q28: =N28-I28 -> 0
A29: ='DIA 08'!A29 -> MG-120 | O29: =J29+C29 -> 0 | P29: =G29-B29 -> 0 | Q29: =N29-I29 -> 0
A30: ='DIA 08'!A30 -> PROSERMIN | C30: 105 | J30: 152 | O30: =J30+C30 -> 257 | P30: =G30-B30 -> 0 | Q30: =N30-I30 -> 0
A31: ='DIA 08'!A31 -> ST-060 | O31: =J31+C31 -> 0 | P31: =G31-B31 -> 0 | Q31: =N31-I31 -> 0
A32: ='DIA 08'!A32 -> ST-53 | O32: =J32+C32 -> 0 | P32: =G32-B32 -> 0 | Q32: =N32-I32 -> 0
A33: ='DIA 08'!A33 -> ST-039 | O33: =J33+C33 -> 0 | P33: =G33-B33 -> 0 | Q33: =N33-I33 -> 0
A34: ='DIA 08'!A34 -> JL-025 | O34: =J34+C34 -> 0 | P34: =G34-B34 -> 0 | Q34: =N34-I34 -> 0
A35: TOTALES | C35: =SUM(C7:C34) -> 803 | J35: =SUM(J7:J34) -> 500 | O35: =C35+J35 -> 1303
A43: NOMBRE Y FIRMA DE QUIEN AUTORIZA | G43: NOMBRE Y FIRMA DE ALMACEN | O43: ADMINISTRADOR
P45: 44237 | R45: 44244 | T45: 44251
O46: ACEITE | P46: TAMBO | Q46: LTS | R46: TAMBO | S46: LTS | T46: TAMBO | U46: LTS
O47: HIDRAULICO | P47: 3 | R47: 2 | S47: 140 | T47: 0 | U47: 155
O48: MOTOR | P48: 3 | Q48: 70 | R48: 2 | S48: 182 | T48: 2 | U48: 170
O49: DIFERENCIAL | P49: 1 | Q49: 137 | R49: 1 | S49: 137 | T49: 1 | U49: 160
O50: MAQ.PERF. | P50: 2 | Q50: 117 | R50: 2 | S50: 27 | T50: 1 | U50: 150
...

Sheet DIA 10
B1: FECHA | E1: MGA CONTRATISTA MINERA S.A. DE C.V. | O1: ENTRADA DE DIESEL | P1: EXISTENCIA INICIAL DE DIESEL (LTS) | Q1: EXISTENCIA FINAL DE DIESEL (LTS)
B2: DIA | C2: MES | D2: AÑO | P2: ='DIA 09'!Q2+O2 -> 6537 | Q2: =P2-O35 -> 5175
A4: NO. DE EQUIPO | B4: PRIMER TURNO | I4: SEGUNDO TURNO
B6: Horometro Inicial 1ra | C6: DIESEL | D6: Nombre Operador | E6: Nombre Despachador | F6: Nombre del supervisor | G6: Horometro Final 1ra | I6: Horometro Inicial 2da | J6: =C6 -> DIESEL | K6: =D6 -> Nombre Operador | L6: =E6 -> Nombre Despachador | M6: =F6 -> Nombre del supervisor | N6: Horometro final 2da | O6: ='DIA 09'!O6 -> CONSUMO X DIA | P6: HRS 1ra | Q6: HRS 2da
A7: ='DIA 09'!A7 -> ST-031 (EPIROC 1030) | O7: =J7+C7 -> 0 | P7: =G7-B7 -> 0 | Q7: =N7-I7 -> 0
A8: ='DIA 09'!A8 -> ST-025 (1600) | O8: =J8+C8 -> 0 | P8: =G8-B8 -> 0 | Q8: =N8-I8 -> 0
A9: ='DIA 09'!A9 -> ST-036 R1300 | B9: 9054.5 | C9: 156 | D9: OÑATE | E9: JOSE | F9: MANUEL | I9: 9060 | J9: 68 | K9: JESUS | L9: CESAR | M9: JESUS | O9: =J9+C9 -> 224 | P9: =G9-B9 -> -9054.5 | Q9: =N9-I9 -> -9060
A10: ='DIA 09'!A10 -> ST-018 | B10: 9674.2 | C10: 169 | D10: OÑATE | E10: JOSE | F10: MANUEL | O10: =J10+C10 -> 169 | P10: =G10-B10 -> -9674.2 | Q10: =N10-I10 -> 0
A11: ='DIA 09'!A11 -> ST-034 KOMATSU | O11: =J11+C11 -> 0 | P11: =G11-B11 -> 0 | Q11: =N11-I11 -> 0
A12: ='DIA 09'!A12 -> JL-015 (DD311) | O12: =J12+C12 -> 0 | P12: =G12-B12 -> 0 | Q12: =N12-I12 -> 0
A13: ='DIA 09'!A13 -> JL-019 | O13: =J13+C13 -> 0 | P13: =G13-B13 -> 0 | Q13: =N13-I13 -> 0
A14: ='DIA 09'!A14 -> JL-024 CANNON | O14: =J14+C14 -> 0 | P14: =G14-B14 -> 0 | Q14: =N14-I14 -> 0
A15: ='DIA 09'!A15 -> JA-007 RESEMIN | I15: 764.5 | J15: 30 | K15: HILARIO | L15: CESAR | M15: JESUS | O15: =J15+C15 -> 30 | P15: =G15-B15 -> 0 | Q15: =N15-I15 -> -764.5
A16: ='DIA 09'!A16 -> JA-004 CANNON | O16: =J16+C16 -> 0 | P16: =G16-B16 -> 0 | Q16: =N16-I16 -> 0
A17: ='DIA 09'!A17 -> RE-009 (RETROEXCAVADORA) | I17: 6694.1 | J17: 61 | K17: ADRIAN | L17: CESAR | M17: JESUS | O17: =J17+C17 -> 61 | P17: =G17-B17 -> 0 | Q17: =N17-I17 -> -6694.1
A18: ='DIA 09'!A18 -> RE-010 (RETROEXCAVADORA) | I18: 2816.2 | J18: 64 | K18: JORGE | L18: CESAR | M18: JESUS | O18: =J18+C18 -> 64 | P18: =G18-B18 -> 0 | Q18: =N18-I18 -> -2816.2
A19: ='DIA 09'!A19 -> ZN | O19: =J19+C19 -> 0 | P19: =G19-B19 -> 0 | Q19: =N19-I19 -> 0
A20: ='DIA 09'!A20 -> CBP-001 (BAJO PERFIL) | O20: =J20+C20 -> 0 | P20: =G20-B20 -> 0 | Q20: =N20-I20 -> 0
A21: ='DIA 09'!A21 -> MG-105 | O21: =J21+C21 -> 0 | P21: =G21-B21 -> 0 | Q21: =N21-I21 -> 0
A22: ='DIA 09'!A22 -> MG-044 | O22: =J22+C22 -> 0 | P22: =G22-B22 -> 0 | Q22: =N22-I22 -> 0
A23: ='DIA 09'!A23 -> MG-085 (POLVORERA) | O23: =J23+C23 -> 0 | P23: =G23-B23 -> 0 | Q23: =N23-I23 -> 0
A24: ='DIA 09'!A24 -> MG-033 (PERSONAL) | C24: 68 | D24: MIGUEL | E24: JOSE | F24: MANUEL | O24: =J24+C24 -> 68 | P24: =G24-B24 -> 0 | Q24: =N24-I24 -> 0
A25: ='DIA 09'!A25 -> MG-113 | O25: =J25+C25 -> 0 | P25: =G25-B25 -> 0 | Q25: =N25-I25 -> 0
A26: ='DIA 09'!A26 -> MG-121 | O26: =J26+C26 -> 0 | P26: =G26-B26 -> 0 | Q26: =N26-I26 -> 0
A27: ='DIA 09'!A27 -> MG-086 | O27: =J27+C27 -> 0 | P27: =G27-B27 -> 0 | Q27: =N27-I27 -> 0
A28: ='DIA 09'!A28 -> MG-111 | O28: =J28+C28 -> 0 | P28: =G28-B28 -> 0 | Q28: =N28-I28 -> 0
A29: ='DIA 09'!A29 -> MG-120 | O29: =J29+C29 -> 0 | P29: =G29-B29 -> 0 | Q29: =N29-I29 -> 0
A30: ='DIA 09'!A30 -> PROSERMIN | C30: 173 | J30: 154 | O30: =J30+C30 -> 327 | P30: =G30-B30 -> 0 | Q30: =N30-I30 -> 0
A31: ='DIA 09'!A31 -> ST-060 | O31: =J31+C31 -> 0 | P31: =G31-B31 -> 0 | Q31: =N31-I31 -> 0
A32: ='DIA 09'!A32 -> ST-53 | O32: =J32+C32 -> 0 | P32: =G32-B32 -> 0 | Q32: =N32-I32 -> 0
A33: ='DIA 09'!A33 -> ST-039 | B33: 9428.2 | C33: 174 | D33: TONY | E33: JOSE | F33: MANUEL | I33: 9436.9 | J33: 199 | K33: CARLOS | L33: CESAR | M33: JESUS | O33: =J33+C33 -> 373 | P33: =G33-B33 -> -9428.2 | Q33: =N33-I33 -> -9436.9
A34: ='DIA 09'!A34 -> JL-025 | I34: 4179.3 | J34: 46 | K34: VICTOR | L34: CESAR | M34: JESUS | O34: =J34+C34 -> 46 | P34: =G34-B34 -> 0 | Q34: =N34-I34 -> -4179.3
A35: TOTALES | C35: =SUM(C7:C34) -> 740 | J35: =SUM(J7:J34) -> 622 | O35: =C35+J35 -> 1362
A43: NOMBRE Y FIRMA DE QUIEN AUTORIZA | G43: NOMBRE Y FIRMA DE ALMACEN | O43: ADMINISTRADOR
P45: 44237 | R45: 44244 | T45: 44251
O46: ACEITE | P46: TAMBO | Q46: LTS | R46: TAMBO | S46: LTS | T46: TAMBO | U46: LTS
O47: HIDRAULICO | P47: 3 | R47: 2 | S47: 140 | T47: 0 | U47: 155
O48: MOTOR | P48: 3 | Q48: 70 | R48: 2 | S48: 182 | T48: 2 | U48: 170
O49: DIFERENCIAL | P49: 1 | Q49: 137 | R49: 1 | S49: 137 | T49: 1 | U49: 160
O50: MAQ.PERF. | P50: 2 | Q50: 117 | R50: 2 | S50: 27 | T50: 1 | U50: 150
...

Sheet DIA 11
B1: FECHA | E1: MGA CONTRATISTA MINERA S.A. DE C.V. | O1: ENTRADA DE DIESEL | P1: EXISTENCIA INICIAL DE DIESEL (LTS) | Q1: EXISTENCIA FINAL DE DIESEL (LTS)
B2: DIA | C2: MES | D2: AÑO | O2: 15850 | P2: ='DIA 10'!Q2+O2 -> 21025 | Q2: =P2-O35 -> 19229
A4: NO. DE EQUIPO | B4: PRIMER TURNO | I4: SEGUNDO TURNO
B6: Horometro Inicial 1ra | C6: DIESEL | D6: Nombre Operador | E6: Nombre Despachador | F6: Nombre del supervisor | G6: Horometro Final 1ra | I6: Horometro Inicial 2da | J6: =C6 -> DIESEL | K6: =D6 -> Nombre Operador | L6: =E6 -> Nombre Despachador | M6: =F6 -> Nombre del supervisor | N6: Horometro final 2da | O6: ='DIA 10'!O6 -> CONSUMO X DIA | P6: HRS 1ra | Q6: HRS 2da
A7: ='DIA 10'!A7 -> ST-031 (EPIROC 1030) | O7: =J7+C7 -> 0 | P7: =G7-B7 -> 0 | Q7: =N7-I7 -> 0
A8: ='DIA 10'!A8 -> ST-025 (1600) | O8: =J8+C8 -> 0 | P8: =G8-B8 -> 0 | Q8: =N8-I8 -> 0
A9: ='DIA 10'!A9 -> ST-036 R1300 | B9: 9069 | C9: 175 | D9: OÑATE | E9: JOSE | F9: MANUEL | I9: 9078.5 | J9: 121 | K9: JESUS | L9: CESAR | M9: JESUS | O9: =J9+C9 -> 296 | P9: =G9-B9 -> -9069 | Q9: =N9-I9 -> -9078.5
A10: ='DIA 10'!A10 -> ST-018 | O10: =J10+C10 -> 0 | P10: =G10-B10 -> 0 | Q10: =N10-I10 -> 0
A11: ='DIA 10'!A11 -> ST-034 KOMATSU | O11: =J11+C11 -> 0 | P11: =G11-B11 -> 0 | Q11: =N11-I11 -> 0
A12: ='DIA 10'!A12 -> JL-015 (DD311) | O12: =J12+C12 -> 0 | P12: =G12-B12 -> 0 | Q12: =N12-I12 -> 0
A13: ='DIA 10'!A13 -> JL-019 | O13: =J13+C13 -> 0 | P13: =G13-B13 -> 0 | Q13: =N13-I13 -> 0
A14: ='DIA 10'!A14 -> JL-024 CANNON | O14: =J14+C14 -> 0 | P14: =G14-B14 -> 0 | Q14: =N14-I14 -> 0
A15: ='DIA 10'!A15 -> JA-007 RESEMIN | O15: =J15+C15 -> 0 | P15: =G15-B15 -> 0 | Q15: =N15-I15 -> 0
A16: ='DIA 10'!A16 -> JA-004 CANNON | O16: =J16+C16 -> 0 | P16: =G16-B16 -> 0 | Q16: =N16-I16 -> 0
A17: ='DIA 10'!A17 -> RE-009 (RETROEXCAVADORA) | I17: 678.4 | J17: 41 | K17: JORGE | L17: CESAR | M17: JESUS | O17: =J17+C17 -> 41 | P17: =G17-B17 -> 0 | Q17: =N17-I17 -> -678.4
A18: ='DIA 10'!A18 -> RE-010 (RETROEXCAVADORA) | I18: 2826.3 | J18: 61 | K18: ADRIAN | L18: CESAR | M18: JESUS | O18: =J18+C18 -> 61 | P18: =G18-B18 -> 0 | Q18: =N18-I18 -> -2826.3
A19: ='DIA 10'!A19 -> ZN | O19: =J19+C19 -> 0 | P19: =G19-B19 -> 0 | Q19: =N19-I19 -> 0
A20: ='DIA 10'!A20 -> CBP-001 (BAJO PERFIL) | O20: =J20+C20 -> 0 | P20: =G20-B20 -> 0 | Q20: =N20-I20 -> 0
A21: ='DIA 10'!A21 -> MG-105 | B21: 5187 | C21: 299 | D21: GERMAN | E21: JOSE | F21: MANUEL | O21: =J21+C21 -> 299 | P21: =G21-B21 -> -5187 | Q21: =N21-I21 -> 0
A22: ='DIA 10'!A22 -> MG-044 | O22: =J22+C22 -> 0 | P22: =G22-B22 -> 0 | Q22: =N22-I22 -> 0
A23: ='DIA 10'!A23 -> MG-085 (POLVORERA) | O23: =J23+C23 -> 0 | P23: =G23-B23 -> 0 | Q23: =N23-I23 -> 0
A24: ='DIA 10'!A24 -> MG-033 (PERSONAL) | O24: =J24+C24 -> 0 | P24: =G24-B24 -> 0 | Q24: =N24-I24 -> 0
A25: ='DIA 10'!A25 -> MG-113 | O25: =J25+C25 -> 0 | P25: =G25-B25 -> 0 | Q25: =N25-I25 -> 0
A26: ='DIA 10'!A26 -> MG-121 | O26: =J26+C26 -> 0 | P26: =G26-B26 -> 0 | Q26: =N26-I26 -> 0
A27: ='DIA 10'!A27 -> MG-086 | O27: =J27+C27 -> 0 | P27: =G27-B27 -> 0 | Q27: =N27-I27 -> 0
A28: ='DIA 10'!A28 -> MG-111 | O28: =J28+C28 -> 0 | P28: =G28-B28 -> 0 | Q28: =N28-I28 -> 0
A29: ='DIA 10'!A29 -> MG-120 | O29: =J29+C29 -> 0 | P29: =G29-B29 -> 0 | Q29: =N29-I29 -> 0
A30: ='DIA 10'!A30 -> PROSERMIN | C30: 367 | J30: 247 | O30: =J30+C30 -> 614 | P30: =G30-B30 -> 0 | Q30: =N30-I30 -> 0
A31: ='DIA 10'!A31 -> ST-060 | O31: =J31+C31 -> 0 | P31: =G31-B31 -> 0 | Q31: =N31-I31 -> 0
A32: ='DIA 10'!A32 -> ST-53 | O32: =J32+C32 -> 0 | P32: =G32-B32 -> 0 | Q32: =N32-I32 -> 0
A33: ='DIA 10'!A33 -> ST-039 | B33: 9445.5 | C33: 248 | D33: TONY | E33: JOSE | F33: MANUEL | I33: 9455.5 | J33: 237 | K33: CARLOS | L33: CESAR | M33: JESUS | O33: =J33+C33 -> 485 | P33: =G33-B33 -> -9445.5 | Q33: =N33-I33 -> -9455.5
A34: ='DIA 10'!A34 -> JL-025 | O34: =J34+C34 -> 0 | P34: =G34-B34 -> 0 | Q34: =N34-I34 -> 0
A35: TOTALES | C35: =SUM(C7:C34) -> 1089 | J35: =SUM(J7:J34) -> 707 | O35: =C35+J35 -> 1796
A43: NOMBRE Y FIRMA DE QUIEN AUTORIZA | G43: NOMBRE Y FIRMA DE ALMACEN | O43: ADMINISTRADOR
P45: 44237 | R45: 44244 | T45: 44251
O46: ACEITE | P46: TAMBO | Q46: LTS | R46: TAMBO | S46: LTS | T46: TAMBO | U46: LTS
O47: HIDRAULICO | P47: 3 | R47: 2 | S47: 140 | T47: 0 | U47: 155
O48: MOTOR | P48: 3 | Q48: 70 | R48: 2 | S48: 182 | T48: 2 | U48: 170
O49: DIFERENCIAL | P49: 1 | Q49: 137 | R49: 1 | S49: 137 | T49: 1 | U49: 160
O50: MAQ.PERF. | P50: 2 | Q50: 117 | R50: 2 | S50: 27 | T50: 1 | U50: 150
...

Sheet DIA 12
B1: FECHA | E1: MGA CONTRATISTA MINERA S.A. DE C.V. | O1: ENTRADA DE DIESEL | P1: EXISTENCIA INICIAL DE DIESEL (LTS) | Q1: EXISTENCIA FINAL DE DIESEL (LTS)
B2: DIA | C2: MES | D2: AÑO | P2: ='DIA 11'!Q2+O2 -> 19229 | Q2: =P2-O35 -> 17444
A4: NO. DE EQUIPO | B4: PRIMER TURNO | I4: SEGUNDO TURNO
B6: Horometro Inicial 1ra | C6: DIESEL | D6: Nombre Operador | E6: Nombre Despachador | F6: Nombre del supervisor | G6: Horometro Final 1ra | I6: Horometro Inicial 2da | J6: =C6 -> DIESEL | K6: =D6 -> Nombre Operador | L6: =E6 -> Nombre Despachador | M6: =F6 -> Nombre del supervisor | N6: Horometro final 2da | O6: ='DIA 11'!O6 -> CONSUMO X DIA | P6: HRS 1ra | Q6: HRS 2da
A7: ='DIA 11'!A7 -> ST-031 (EPIROC 1030) | O7: =J7+C7 -> 0 | P7: =G7-B7 -> 0 | Q7: =N7-I7 -> 0
A8: ='DIA 11'!A8 -> ST-025 (1600) | O8: =J8+C8 -> 0 | P8: =G8-B8 -> 0 | Q8: =N8-I8 -> 0
A9: ='DIA 11'!A9 -> ST-036 R1300 | B9: 9086.8 | C9: 172 | D9: OÑATE | E9: JOSE | F9: MANUEL | I9: 9091.8 | J9: 62 | K9: JESUS | L9: CESAR | M9: JESUS | O9: =J9+C9 -> 234 | P9: =G9-B9 -> -9086.8 | Q9: =N9-I9 -> -9091.8
A10: ='DIA 11'!A10 -> ST-018 | O10: =J10+C10 -> 0 | P10: =G10-B10 -> 0 | Q10: =N10-I10 -> 0
A11: ='DIA 11'!A11 -> ST-034 KOMATSU | O11: =J11+C11 -> 0 | P11: =G11-B11 -> 0 | Q11: =N11-I11 -> 0
A12: ='DIA 11'!A12 -> JL-015 (DD311) | O12: =J12+C12 -> 0 | P12: =G12-B12 -> 0 | Q12: =N12-I12 -> 0
A13: ='DIA 11'!A13 -> JL-019 | O13: =J13+C13 -> 0 | P13: =G13-B13 -> 0 | Q13: =N13-I13 -> 0
A14: ='DIA 11'!A14 -> JL-024 CANNON | O14: =J14+C14 -> 0 | P14: =G14-B14 -> 0 | Q14: =N14-I14 -> 0
A15: ='DIA 11'!A15 -> JA-007 RESEMIN | O15: =J15+C15 -> 0 | P15: =G15-B15 -> 0 | Q15: =N15-I15 -> 0
A16: ='DIA 11'!A16 -> JA-004 CANNON | O16: =J16+C16 -> 0 | P16: =G16-B16 -> 0 | Q16: =N16-I16 -> 0
A17: ='DIA 11'!A17 -> RE-009 (RETROEXCAVADORA) | B17: 6413.2 | C17: 44 | D17: CRISTIAN | E17: JOSE | F17: MANUEL | O17: =J17+C17 -> 44 | P17: =G17-B17 -> -6413.2 | Q17: =N17-I17 -> 0
A18: ='DIA 11'!A18 -> RE-010 (RETROEXCAVADORA) | O18: =J18+C18 -> 0 | P18: =G18-B18 -> 0 | Q18: =N18-I18 -> 0
A19: ='DIA 11'!A19 -> ZN | O19: =J19+C19 -> 0 | P19: =G19-B19 -> 0 | Q19: =N19-I19 -> 0
A20: ='DIA 11'!A20 -> CBP-001 (BAJO PERFIL) | O20: =J20+C20 -> 0 | P20: =G20-B20 -> 0 | Q20: =N20-I20 -> 0
A21: ='DIA 11'!A21 -> MG-105 | O21: =J21+C21 -> 0 | P21: =G21-B21 -> 0 | Q21: =N21-I21 -> 0
A22: ='DIA 11'!A22 -> MG-044 | O22: =J22+C22 -> 0 | P22: =G22-B22 -> 0 | Q22: =N22-I22 -> 0
A23: ='DIA 11'!A23 -> MG-085 (POLVORERA) | O23: =J23+C23 -> 0 | P23: =G23-B23 -> 0 | Q23: =N23-I23 -> 0
A24: ='DIA 11'!A24 -> MG-033 (PERSONAL) | O24: =J24+C24 -> 0 | P24: =G24-B24 -> 0 | Q24: =N24-I24 -> 0
A25: ='DIA 11'!A25 -> MG-113 | O25: =J25+C25 -> 0 | P25: =G25-B25 -> 0 | Q25: =N25-I25 -> 0
A26: ='DIA 11'!A26 -> MG-121 | O26: =J26+C26 -> 0 | P26: =G26-B26 -> 0 | Q26: =N26-I26 -> 0
A27: ='DIA 11'!A27 -> MG-086 | O27: =J27+C27 -> 0 | P27: =G27-B27 -> 0 | Q27: =N27-I27 -> 0
A28: ='DIA 11'!A28 -> MG-111 | O28: =J28+C28 -> 0 | P28: =G28-B28 -> 0 | Q28: =N28-I28 -> 0
A29: ='DIA 11'!A29 -> MG-120 | O29: =J29+C29 -> 0 | P29: =G29-B29 -> 0 | Q29: =N29-I29 -> 0
A30: ='DIA 11'!A30 -> PROSERMIN | C30: 499 | J30: 335 | O30: =J30+C30 -> 834 | P30: =G30-B30 -> 0 | Q30: =N30-I30 -> 0
A31: ='DIA 11'!A31 -> ST-060 | O31: =J31+C31 -> 0 | P31: =G31-B31 -> 0 | Q31: =N31-I31 -> 0
A32: ='DIA 11'!A32 -> ST-53 | O32: =J32+C32 -> 0 | P32: =G32-B32 -> 0 | Q32: =N32-I32 -> 0
A33: ='DIA 11'!A33 -> ST-039 | B33: 9464.1 | C33: 228 | D33: TONY | E33: JOSE | F33: MANUEL | I33: 9473.4 | J33: 445 | K33: CARLOS | L33: CESAR | M33: JESUS | O33: =J33+C33 -> 673 | P33: =G33-B33 -> -9464.1 | Q33: =N33-I33 -> -9473.4
A34: ='DIA 11'!A34 -> JL-025 | O34: =J34+C34 -> 0 | P34: =G34-B34 -> 0 | Q34: =N34-I34 -> 0
A35: TOTALES | C35: =SUM(C7:C34) -> 943 | J35: =SUM(J7:J34) -> 842 | O35: =C35+J35 -> 1785
A43: NOMBRE Y FIRMA DE QUIEN AUTORIZA | G43: NOMBRE Y FIRMA DE ALMACEN | O43: ADMINISTRADOR
P45: 44237 | R45: 44244 | T45: 44251
O46: ACEITE | P46: TAMBO | Q46: LTS | R46: TAMBO | S46: LTS | T46: TAMBO | U46: LTS
O47: HIDRAULICO | P47: 3 | R47: 2 | S47: 140 | T47: 0 | U47: 155
O48: MOTOR | P48: 3 | Q48: 70 | R48: 2 | S48: 182 | T48: 2 | U48: 170
O49: DIFERENCIAL | P49: 1 | Q49: 137 | R49: 1 | S49: 137 | T49: 1 | U49: 160
O50: MAQ.PERF. | P50: 2 | Q50: 117 | R50: 2 | S50: 27 | T50: 1 | U50: 150
...

Sheet DIA 13
B1: FECHA | E1: MGA CONTRATISTA MINERA S.A. DE C.V. | O1: ENTRADA DE DIESEL | P1: EXISTENCIA INICIAL DE DIESEL (LTS) | Q1: EXISTENCIA FINAL DE DIESEL (LTS)
B2: DIA | C2: MES | D2: AÑO | P2: ='DIA 12'!Q2+O2 -> 17444 | Q2: =P2-O35 -> 11828
A4: NO. DE EQUIPO | B4: PRIMER TURNO | I4: SEGUNDO TURNO
B6: Horometro Inicial 1ra | C6: DIESEL | D6: Nombre Operador | E6: Nombre Despachador | F6: Nombre del supervisor | G6: Horometro Final 1ra | I6: Horometro Inicial 2da | J6: =C6 -> DIESEL | K6: =D6 -> Nombre Operador | L6: =E6 -> Nombre Despachador | M6: =F6 -> Nombre del supervisor | N6: Horometro final 2da | O6: ='DIA 12'!O6 -> CONSUMO X DIA | P6: HRS 1ra | Q6: HRS 2da
A7: ='DIA 12'!A7 -> ST-031 (EPIROC 1030) | O7: =J7+C7 -> 0 | P7: =G7-B7 -> 0 | Q7: =N7-I7 -> 0
A8: ='DIA 12'!A8 -> ST-025 (1600) | B8: 9098 | C8: 105 | D8: OÑATE | E8: JOSE | F8: MANUEL | I8: 9106.6 | J8: 124 | K8: JESUS | L8: CESAR | M8: JESUS | O8: =J8+C8 -> 229 | P8: =G8-B8 -> -9098 | Q8: =N8-I8 -> -9106.6
A9: ='DIA 12'!A9 -> ST-036 R1300 | O9: =J9+C9 -> 0 | P9: =G9-B9 -> 0 | Q9: =N9-I9 -> 0
A10: ='DIA 12'!A10 -> ST-018 | O10: =J10+C10 -> 0 | P10: =G10-B10 -> 0 | Q10: =N10-I10 -> 0
A11: ='DIA 12'!A11 -> ST-034 KOMATSU | O11: =J11+C11 -> 0 | P11: =G11-B11 -> 0 | Q11: =N11-I11 -> 0
A12: ='DIA 12'!A12 -> JL-015 (DD311) | J12: 56 | K12: WILFREDO | L12: CESAR | M12: JESUS | O12: =J12+C12 -> 56 | P12: =G12-B12 -> 0 | Q12: =N12-I12 -> 0
A13: ='DIA 12'!A13 -> JL-019 | O13: =J13+C13 -> 0 | P13: =G13-B13 -> 0 | Q13: =N13-I13 -> 0
A14: ='DIA 12'!A14 -> JL-024 CANNON | O14: =J14+C14 -> 0 | P14: =G14-B14 -> 0 | Q14: =N14-I14 -> 0
A15: ='DIA 12'!A15 -> JA-007 RESEMIN | O15: =J15+C15 -> 0 | P15: =G15-B15 -> 0 | Q15: =N15-I15 -> 0
A16: ='DIA 12'!A16 -> JA-004 CANNON | O16: =J16+C16 -> 0 | P16: =G16-B16 -> 0 | Q16: =N16-I16 -> 0
A17: ='DIA 12'!A17 -> RE-009 (RETROEXCAVADORA) | B17: 6227.2 | C17: 43 | D17: CISTIAN | E17: JOSE | F17: MANUEL | O17: =J17+C17 -> 43 | P17: =G17-B17 -> -6227.2 | Q17: =N17-I17 -> 0
A18: ='DIA 12'!A18 -> RE-010 (RETROEXCAVADORA) | I18: 2852.5 | J18: 95 | K18: ADRIAN | L18: CESAR | M18: JESUS | O18: =J18+C18 -> 95 | P18: =G18-B18 -> 0 | Q18: =N18-I18 -> -2852.5
A19: ='DIA 12'!A19 -> ZN | C19: 4002 | D19: JUAN | E19: JOSE | F19: MANUEL | O19: =J19+C19 -> 4002 | P19: =G19-B19 -> 0 | Q19: =N19-I19 -> 0
A20: ='DIA 12'!A20 -> CBP-001 (BAJO PERFIL) | O20: =J20+C20 -> 0 | P20: =G20-B20 -> 0 | Q20: =N20-I20 -> 0
A21: ='DIA 12'!A21 -> MG-105 | O21: =J21+C21 -> 0 | P21: =G21-B21 -> 0 | Q21: =N21-I21 -> 0
A22: ='DIA 12'!A22 -> MG-044 | B22: 13224 | C22: 239 | D22: GERMAN | E22: JOSE | F22: MANUEL | O22: =J22+C22 -> 239 | P22: =G22-B22 -> -13224 | Q22: =N22-I22 -> 0
A23: ='DIA 12'!A23 -> MG-085 (POLVORERA) | O23: =J23+C23 -> 0 | P23: =G23-B23 -> 0 | Q23: =N23-I23 -> 0
A24: ='DIA 12'!A24 -> MG-033 (PERSONAL) | O24: =J24+C24 -> 0 | P24: =G24-B24 -> 0 | Q24: =N24-I24 -> 0
A25: ='DIA 12'!A25 -> MG-113 | B25: 24060 | C25: 71 | D25: ROGELIO | E25: JOSE | F25: MANUEL | O25: =J25+C25 -> 71 | P25: =G25-B25 -> -24060 | Q25: =N25-I25 -> 0
A26: ='DIA 12'!A26 -> MG-121 | O26: =J26+C26 -> 0 | P26: =G26-B26 -> 0 | Q26: =N26-I26 -> 0
A27: ='DIA 12'!A27 -> MG-086 | O27: =J27+C27 -> 0 | P27: =G27-B27 -> 0 | Q27: =N27-I27 -> 0
A28: ='DIA 12'!A28 -> MG-111 | O28: =J28+C28 -> 0 | P28: =G28-B28 -> 0 | Q28: =N28-I28 -> 0
A29: ='DIA 12'!A29 -> MG-120 | O29: =J29+C29 -> 0 | P29: =G29-B29 -> 0 | Q29: =N29-I29 -> 0
A30: ='DIA 12'!A30 -> PROSERMIN | C30: 286 | J30: 182 | O30: =J30+C30 -> 468 | P30: =G30-B30 -> 0 | Q30: =N30-I30 -> 0
A31: ='DIA 12'!A31 -> ST-060 | O31: =J31+C31 -> 0 | P31: =G31-B31 -> 0 | Q31: =N31-I31 -> 0
A32: ='DIA 12'!A32 -> ST-53 | O32: =J32+C32 -> 0 | P32: =G32-B32 -> 0 | Q32: =N32-I32 -> 0
A33: ='DIA 12'!A33 -> ST-039 | B33: 9489.6 | C33: 204 | D33: TONY | E33: JOSE | F33: MANUEL | I33: 9498.3 | J33: 209 | K33: CARLOS | L33: CESAR | M33: JESUS | O33: =J33+C33 -> 413 | P33: =G33-B33 -> -9489.6 | Q33: =N33-I33 -> -9498.3
A34: ='DIA 12'!A34 -> JL-025 | O34: =J34+C34 -> 0 | P34: =G34-B34 -> 0 | Q34: =N34-I34 -> 0
A35: TOTALES | C35: =SUM(C7:C34) -> 4950 | J35: =SUM(J7:J34) -> 666 | O35: =C35+J35 -> 5616
A43: NOMBRE Y FIRMA DE QUIEN AUTORIZA | G43: NOMBRE Y FIRMA DE ALMACEN | O43: ADMINISTRADOR
P45: 44237 | R45: 44244 | T45: 44251
O46: ACEITE | P46: TAMBO | Q46: LTS | R46: TAMBO | S46: LTS | T46: TAMBO | U46: LTS
O47: HIDRAULICO | P47: 3 | R47: 2 | S47: 140 | T47: 0 | U47: 155
O48: MOTOR | P48: 3 | Q48: 70 | R48: 2 | S48: 182 | T48: 2 | U48: 170
O49: DIFERENCIAL | P49: 1 | Q49: 137 | R49: 1 | S49: 137 | T49: 1 | U49: 160
O50: MAQ.PERF. | P50: 2 | Q50: 117 | R50: 2 | S50: 27 | T50: 1 | U50: 150
...

Sheet DIA 14
B1: FECHA | E1: MGA CONTRATISTA MINERA S.A. DE C.V. | O1: ENTRADA DE DIESEL | P1: EXISTENCIA INICIAL DE DIESEL (LTS) | Q1: EXISTENCIA FINAL DE DIESEL (LTS)
B2: DIA | C2: MES | D2: AÑO | O2: 1800 | P2: ='DIA 13'!Q2+O2 -> 13628 | Q2: =P2-O35 -> 11811
A4: NO. DE EQUIPO | B4: PRIMER TURNO | I4: SEGUNDO TURNO
B6: Horometro Inicial 1ra | C6: DIESEL | D6: Nombre Operador | E6: Nombre Despachador | F6: Nombre del supervisor | G6: Horometro Final 1ra | I6: Horometro Inicial 2da | J6: =C6 -> DIESEL | K6: =D6 -> Nombre Operador | L6: =E6 -> Nombre Despachador | M6: =F6 -> Nombre del supervisor | N6: Horometro final 2da | O6: ='DIA 13'!O6 -> CONSUMO X DIA | P6: HRS 1ra | Q6: HRS 2da
A7: ='DIA 13'!A7 -> ST-031 (EPIROC 1030) | O7: =J7+C7 -> 0 | P7: =G7-B7 -> 0 | Q7: =N7-I7 -> 0
A8: ='DIA 13'!A8 -> ST-025 (1600) | O8: =J8+C8 -> 0 | P8: =G8-B8 -> 0 | Q8: =N8-I8 -> 0
A9: ='DIA 13'!A9 -> ST-036 R1300 | B9: 9115 | C9: 138 | D9: OÑATE | E9: JOSE | F9: MANUEL | I9: 9123.5 | J9: 135 | K9: JESUS | L9: CESAR | M9: JESUS | O9: =J9+C9 -> 273 | P9: =G9-B9 -> -9115 | Q9: =N9-I9 -> -9123.5
A10: ='DIA 13'!A10 -> ST-018 | O10: =J10+C10 -> 0 | P10: =G10-B10 -> 0 | Q10: =N10-I10 -> 0
A11: ='DIA 13'!A11 -> ST-034 KOMATSU | O11: =J11+C11 -> 0 | P11: =G11-B11 -> 0 | Q11: =N11-I11 -> 0
A12: ='DIA 13'!A12 -> JL-015 (DD311) | O12: =J12+C12 -> 0 | P12: =G12-B12 -> 0 | Q12: =N12-I12 -> 0
A13: ='DIA 13'!A13 -> JL-019 | O13: =J13+C13 -> 0 | P13: =G13-B13 -> 0 | Q13: =N13-I13 -> 0
